Workbook

Sheet Лист1
B1: Блок | C1: БВ | G1: БОВ | L1: БГ | O1: БОВГ
A2: Нагрузка | C2: xx | D2: РП | E2: Рх | F2: хП | G2: С | H2: Т | I2: Т-2(50%) | J2: Т-2(75%) | K2: Т-2(100%) | M2: С | N2: П | P2: С | Q2: П
A3: 0.05 | C3: =$C$1&"-"&$A3&"-"&C$2 -> БВ-0,05-xx | D3: =$C$1&"-"&$A3&"-"&D$2 -> БВ-0,05-РП | E3: =$C$1&"-"&$A3&"-"&E$2 -> БВ-0,05-Рх | F3: =$C$1&"-"&$A3&"-"&F$2 -> БВ-0,05-хП | G3: =$G$1&"-"&$A3&"-"&G$2 -> БОВ-0,05-С | H3: =$G$1&"-"&$A3&"-"&H$2 -> БОВ-0,05-Т | I3: =$G$1&"-"&$A3&"-"&I$2 -> БОВ-0,05-Т-2(50%) | J3: =$G$1&"-"&$A3&"-"&J$2 -> БОВ-0,05-Т-2(75%) | K3: =$G$1&"-"&$A3&"-"&K$2 -> БОВ-0,05-Т-2(100%) | L3: =$L$1&"-"&$A3 -> БГ-0,05 | M3: =$L$1&"-"&M$2&"-"&$A3&"/"&$A3 -> БГ-С-0,05/0,05 | N3: =$L$1&"-"&N$2&"-"&$A3&"/"&$A3 -> БГ-П-0,05/0,05 | O3: =$O$1&"-"&$A3 -> БОВГ-0,05 | P3: =$O$1&"-"&P$2&"-"&$A3&"/"&$A3 -> БОВГ-С-0,05/0,05 | Q3: =$O$1&"-"&Q$2&"-"&$A3&"/"&$A3 -> БОВГ-П-0,05/0,05
A4: 0.06 | C4: =$C$1&"-"&$A4&"-"&C$2 -> БВ-0,06-xx | D4: =$C$1&"-"&$A4&"-"&D$2 -> БВ-0,06-РП | E4: =$C$1&"-"&$A4&"-"&E$2 -> БВ-0,06-Рх | F4: =$C$1&"-"&$A4&"-"&F$2 -> БВ-0,06-хП | G4: =$G$1&"-"&$A4&"-"&G$2 -> БОВ-0,06-С | H4: =$G$1&"-"&$A4&"-"&H$2 -> БОВ-0,06-Т | I4: =$G$1&"-"&$A4&"-"&I$2 -> БОВ-0,06-Т-2(50%) | J4: =$G$1&"-"&$A4&"-"&J$2 -> БОВ-0,06-Т-2(75%) | K4: =$G$1&"-"&$A4&"-"&K$2 -> БОВ-0,06-Т-2(100%) | L4: =$L$1&"-"&$A4 -> БГ-0,06 | M4: =$L$1&"-"&M$2&"-"&$A4&"/"&$A4 -> БГ-С-0,06/0,06 | N4: =$L$1&"-"&N$2&"-"&$A4&"/"&$A4 -> БГ-П-0,06/0,06 | O4: =$O$1&"-"&$A4 -> БОВГ-0,06 | P4: =$O$1&"-"&P$2&"-"&$A4&"/"&$A4 -> БОВГ-С-0,06/0,06 | Q4: =$O$1&"-"&Q$2&"-"&$A4&"/"&$A4 -> БОВГ-П-0,06/0,06
A5: 0.07 | C5: =$C$1&"-"&$A5&"-"&C$2 -> БВ-0,07-xx | D5: =$C$1&"-"&$A5&"-"&D$2 -> БВ-0,07-РП | E5: =$C$1&"-"&$A5&"-"&E$2 -> БВ-0,07-Рх | F5: =$C$1&"-"&$A5&"-"&F$2 -> БВ-0,07-хП | G5: =$G$1&"-"&$A5&"-"&G$2 -> БОВ-0,07-С | H5: =$G$1&"-"&$A5&"-"&H$2 -> БОВ-0,07-Т | I5: =$G$1&"-"&$A5&"-"&I$2 -> БОВ-0,07-Т-2(50%) | J5: =$G$1&"-"&$A5&"-"&J$2 -> БОВ-0,07-Т-2(75%) | K5: =$G$1&"-"&$A5&"-"&K$2 -> БОВ-0,07-Т-2(100%) | L5: =$L$1&"-"&$A5 -> БГ-0,07 | M5: =$L$1&"-"&M$2&"-"&$A5&"/"&$A5 -> БГ-С-0,07/0,07 | N5: =$L$1&"-"&N$2&"-"&$A5&"/"&$A5 -> БГ-П-0,07/0,07 | O5: =$O$1&"-"&$A5 -> БОВГ-0,07 | P5: =$O$1&"-"&P$2&"-"&$A5&"/"&$A5 -> БОВГ-С-0,07/0,07 | Q5: =$O$1&"-"&Q$2&"-"&$A5&"/"&$A5 -> БОВГ-П-0,07/0,07
A6: 0.08 | C6: =$C$1&"-"&$A6&"-"&C$2 -> БВ-0,08-xx | D6: =$C$1&"-"&$A6&"-"&D$2 -> БВ-0,08-РП | E6: =$C$1&"-"&$A6&"-"&E$2 -> БВ-0,08-Рх | F6: =$C$1&"-"&$A6&"-"&F$2 -> БВ-0,08-хП | G6: =$G$1&"-"&$A6&"-"&G$2 -> БОВ-0,08-С | H6: =$G$1&"-"&$A6&"-"&H$2 -> БОВ-0,08-Т | I6: =$G$1&"-"&$A6&"-"&I$2 -> БОВ-0,08-Т-2(50%) | J6: =$G$1&"-"&$A6&"-"&J$2 -> БОВ-0,08-Т-2(75%) | K6: =$G$1&"-"&$A6&"-"&K$2 -> БОВ-0,08-Т-2(100%) | L6: =$L$1&"-"&$A6 -> БГ-0,08 | M6: =$L$1&"-"&M$2&"-"&$A6&"/"&$A6 -> БГ-С-0,08/0,08 | N6: =$L$1&"-"&N$2&"-"&$A6&"/"&$A6 -> БГ-П-0,08/0,08 | O6: =$O$1&"-"&$A6 -> БОВГ-0,08 | P6: =$O$1&"-"&P$2&"-"&$A6&"/"&$A6 -> БОВГ-С-0,08/0,08 | Q6: =$O$1&"-"&Q$2&"-"&$A6&"/"&$A6 -> БОВГ-П-0,08/0,08
A7: 0.09 | C7: =$C$1&"-"&$A7&"-"&C$2 -> БВ-0,09-xx | D7: =$C$1&"-"&$A7&"-"&D$2 -> БВ-0,09-РП | E7: =$C$1&"-"&$A7&"-"&E$2 -> БВ-0,09-Рх | F7: =$C$1&"-"&$A7&"-"&F$2 -> БВ-0,09-хП | G7: =$G$1&"-"&$A7&"-"&G$2 -> БОВ-0,09-С | H7: =$G$1&"-"&$A7&"-"&H$2 -> БОВ-0,09-Т | I7: =$G$1&"-"&$A7&"-"&I$2 -> БОВ-0,09-Т-2(50%) | J7: =$G$1&"-"&$A7&"-"&J$2 -> БОВ-0,09-Т-2(75%) | K7: =$G$1&"-"&$A7&"-"&K$2 -> БОВ-0,09-Т-2(100%) | L7: =$L$1&"-"&$A7 -> БГ-0,09 | M7: =$L$1&"-"&M$2&"-"&$A7&"/"&$A7 -> БГ-С-0,09/0,09 | N7: =$L$1&"-"&N$2&"-"&$A7&"/"&$A7 -> БГ-П-0,09/0,09 | O7: =$O$1&"-"&$A7 -> БОВГ-0,09 | P7: =$O$1&"-"&P$2&"-"&$A7&"/"&$A7 -> БОВГ-С-0,09/0,09 | Q7: =$O$1&"-"&Q$2&"-"&$A7&"/"&$A7 -> БОВГ-П-0,09/0,09
A8: 0,10 | C8: =$C$1&"-"&$A8&"-"&C$2 -> БВ-0,10-xx | D8: =$C$1&"-"&$A8&"-"&D$2 -> БВ-0,10-РП | E8: =$C$1&"-"&$A8&"-"&E$2 -> БВ-0,10-Рх | F8: =$C$1&"-"&$A8&"-"&F$2 -> БВ-0,10-хП | G8: =$G$1&"-"&$A8&"-"&G$2 -> БОВ-0,10-С | H8: =$G$1&"-"&$A8&"-"&H$2 -> БОВ-0,10-Т | I8: =$G$1&"-"&$A8&"-"&I$2 -> БОВ-0,10-Т-2(50%) | J8: =$G$1&"-"&$A8&"-"&J$2 -> БОВ-0,10-Т-2(75%) | K8: =$G$1&"-"&$A8&"-"&K$2 -> БОВ-0,10-Т-2(100%) | L8: =$L$1&"-"&$A8 -> БГ-0,10 | M8: =$L$1&"-"&M$2&"-"&$A8&"/"&$A8 -> БГ-С-0,10/0,10 | N8: =$L$1&"-"&N$2&"-"&$A8&"/"&$A8 -> БГ-П-0,10/0,10 | O8: =$O$1&"-"&$A8 -> БОВГ-0,10 | P8: =$O$1&"-"&P$2&"-"&$A8&"/"&$A8 -> БОВГ-С-0,10/0,10 | Q8: =$O$1&"-"&Q$2&"-"&$A8&"/"&$A8 -> БОВГ-П-0,10/0,10
A9: 0.15 | C9: =$C$1&"-"&$A9&"-"&C$2 -> БВ-0,15-xx | D9: =$C$1&"-"&$A9&"-"&D$2 -> БВ-0,15-РП | E9: =$C$1&"-"&$A9&"-"&E$2 -> БВ-0,15-Рх | F9: =$C$1&"-"&$A9&"-"&F$2 -> БВ-0,15-хП | G9: =$G$1&"-"&$A9&"-"&G$2 -> БОВ-0,15-С | H9: =$G$1&"-"&$A9&"-"&H$2 -> БОВ-0,15-Т | I9: =$G$1&"-"&$A9&"-"&I$2 -> БОВ-0,15-Т-2(50%) | J9: =$G$1&"-"&$A9&"-"&J$2 -> БОВ-0,15-Т-2(75%) | K9: =$G$1&"-"&$A9&"-"&K$2 -> БОВ-0,15-Т-2(100%) | L9: =$L$1&"-"&$A9 -> БГ-0,15 | M9: =$L$1&"-"&M$2&"-"&$A9&"/"&$A9 -> БГ-С-0,15/0,15 | N9: =$L$1&"-"&N$2&"-"&$A9&"/"&$A9 -> БГ-П-0,15/0,15 | O9: =$O$1&"-"&$A9 -> БОВГ-0,15 | P9: =$O$1&"-"&P$2&"-"&$A9&"/"&$A9 -> БОВГ-С-0,15/0,15 | Q9: =$O$1&"-"&Q$2&"-"&$A9&"/"&$A9 -> БОВГ-П-0,15/0,15
A10: 0,20 | C10: =$C$1&"-"&$A10&"-"&C$2 -> БВ-0,20-xx | D10: =$C$1&"-"&$A10&"-"&D$2 -> БВ-0,20-РП | E10: =$C$1&"-"&$A10&"-"&E$2 -> БВ-0,20-Рх | F10: =$C$1&"-"&$A10&"-"&F$2 -> БВ-0,20-хП | G10: =$G$1&"-"&$A10&"-"&G$2 -> БОВ-0,20-С | H10: =$G$1&"-"&$A10&"-"&H$2 -> БОВ-0,20-Т | I10: =$G$1&"-"&$A10&"-"&I$2 -> БОВ-0,20-Т-2(50%) | J10: =$G$1&"-"&$A10&"-"&J$2 -> БОВ-0,20-Т-2(75%) | K10: =$G$1&"-"&$A10&"-"&K$2 -> БОВ-0,20-Т-2(100%) | L10: =$L$1&"-"&$A10 -> БГ-0,20 | M10: =$L$1&"-"&M$2&"-"&$A10&"/"&$A10 -> БГ-С-0,20/0,20 | N10: =$L$1&"-"&N$2&"-"&$A10&"/"&$A10 -> БГ-П-0,20/0,20 | O10: =$O$1&"-"&$A10 -> БОВГ-0,20 | P10: =$O$1&"-"&P$2&"-"&$A10&"/"&$A10 -> БОВГ-С-0,20/0,20 | Q10: =$O$1&"-"&Q$2&"-"&$A10&"/"&$A10 -> БОВГ-П-0,20/0,20
A11: 0.25 | C11: =$C$1&"-"&$A11&"-"&C$2 -> БВ-0,25-xx | D11: =$C$1&"-"&$A11&"-"&D$2 -> БВ-0,25-РП | E11: =$C$1&"-"&$A11&"-"&E$2 -> БВ-0,25-Рх | F11: =$C$1&"-"&$A11&"-"&F$2 -> БВ-0,25-хП | G11: =$G$1&"-"&$A11&"-"&G$2 -> БОВ-0,25-С | H11: =$G$1&"-"&$A11&"-"&H$2 -> БОВ-0,25-Т | I11: =$G$1&"-"&$A11&"-"&I$2 -> БОВ-0,25-Т-2(50%) | J11: =$G$1&"-"&$A11&"-"&J$2 -> БОВ-0,25-Т-2(75%) | K11: =$G$1&"-"&$A11&"-"&K$2 -> БОВ-0,25-Т-2(100%) | L11: =$L$1&"-"&$A11 -> БГ-0,25 | M11: =$L$1&"-"&M$2&"-"&$A11&"/"&$A11 -> БГ-С-0,25/0,25 | N11: =$L$1&"-"&N$2&"-"&$A11&"/"&$A11 -> БГ-П-0,25/0,25 | O11: =$O$1&"-"&$A11 -> БОВГ-0,25 | P11: =$O$1&"-"&P$2&"-"&$A11&"/"&$A11 -> БОВГ-С-0,25/0,25 | Q11: =$O$1&"-"&Q$2&"-"&$A11&"/"&$A11 -> БОВГ-П-0,25/0,25
A12: 0,30 | C12: =$C$1&"-"&$A12&"-"&C$2 -> БВ-0,30-xx | D12: =$C$1&"-"&$A12&"-"&D$2 -> БВ-0,30-РП | E12: =$C$1&"-"&$A12&"-"&E$2 -> БВ-0,30-Рх | F12: =$C$1&"-"&$A12&"-"&F$2 -> БВ-0,30-хП | G12: =$G$1&"-"&$A12&"-"&G$2 -> БОВ-0,30-С | H12: =$G$1&"-"&$A12&"-"&H$2 -> БОВ-0,30-Т | I12: =$G$1&"-"&$A12&"-"&I$2 -> БОВ-0,30-Т-2(50%) | J12: =$G$1&"-"&$A12&"-"&J$2 -> БОВ-0,30-Т-2(75%) | K12: =$G$1&"-"&$A12&"-"&K$2 -> БОВ-0,30-Т-2(100%) | L12: =$L$1&"-"&$A12 -> БГ-0,30 | M12: =$L$1&"-"&M$2&"-"&$A12&"/"&$A12 -> БГ-С-0,30/0,30 | N12: =$L$1&"-"&N$2&"-"&$A12&"/"&$A12 -> БГ-П-0,30/0,30 | O12: =$O$1&"-"&$A12 -> БОВГ-0,30 | P12: =$O$1&"-"&P$2&"-"&$A12&"/"&$A12 -> БОВГ-С-0,30/0,30 | Q12: =$O$1&"-"&Q$2&"-"&$A12&"/"&$A12 -> БОВГ-П-0,30/0,30
A13: 0.35 | C13: =$C$1&"-"&$A13&"-"&C$2 -> БВ-0,35-xx | D13: =$C$1&"-"&$A13&"-"&D$2 -> БВ-0,35-РП | E13: =$C$1&"-"&$A13&"-"&E$2 -> БВ-0,35-Рх | F13: =$C$1&"-"&$A13&"-"&F$2 -> БВ-0,35-хП | G13: =$G$1&"-"&$A13&"-"&G$2 -> БОВ-0,35-С | H13: =$G$1&"-"&$A13&"-"&H$2 -> БОВ-0,35-Т | I13: =$G$1&"-"&$A13&"-"&I$2 -> БОВ-0,35-Т-2(50%) | J13: =$G$1&"-"&$A13&"-"&J$2 -> БОВ-0,35-Т-2(75%) | K13: =$G$1&"-"&$A13&"-"&K$2 -> БОВ-0,35-Т-2(100%) | L13: =$L$1&"-"&$A13 -> БГ-0,35 | M13: =$L$1&"-"&M$2&"-"&$A13&"/"&$A13 -> БГ-С-0,35/0,35 | N13: =$L$1&"-"&N$2&"-"&$A13&"/"&$A13 -> БГ-П-0,35/0,35 | O13: =$O$1&"-"&$A13 -> БОВГ-0,35 | P13: =$O$1&"-"&P$2&"-"&$A13&"/"&$A13 -> БОВГ-С-0,35/0,35 | Q13: =$O$1&"-"&Q$2&"-"&$A13&"/"&$A13 -> БОВГ-П-0,35/0,35
A14: 0,04 | C14: =$C$1&"-"&$A14&"-"&C$2 -> БВ-0,04-xx | D14: =$C$1&"-"&$A14&"-"&D$2 -> БВ-0,04-РП | E14: =$C$1&"-"&$A14&"-"&E$2 -> БВ-0,04-Рх | F14: =$C$1&"-"&$A14&"-"&F$2 -> БВ-0,04-хП | G14: =$G$1&"-"&$A14&"-"&G$2 -> БОВ-0,04-С | H14: =$G$1&"-"&$A14&"-"&H$2 -> БОВ-0,04-Т | I14: =$G$1&"-"&$A14&"-"&I$2 -> БОВ-0,04-Т-2(50%) | J14: =$G$1&"-"&$A14&"-"&J$2 -> БОВ-0,04-Т-2(75%) | K14: =$G$1&"-"&$A14&"-"&K$2 -> БОВ-0,04-Т-2(100%) | L14: =$L$1&"-"&$A14 -> БГ-0,04 | M14: =$L$1&"-"&M$2&"-"&$A14&"/"&$A14 -> БГ-С-0,04/0,04 | N14: =$L$1&"-"&N$2&"-"&$A14&"/"&$A14 -> БГ-П-0,04/0,04 | O14: =$O$1&"-"&$A14 -> БОВГ-0,04 | P14: =$O$1&"-"&P$2&"-"&$A14&"/"&$A14 -> БОВГ-С-0,04/0,04 | Q14: =$O$1&"-"&Q$2&"-"&$A14&"/"&$A14 -> БОВГ-П-0,04/0,04
A15: 0.45 | C15: =$C$1&"-"&$A15&"-"&C$2 -> БВ-0,45-xx | D15: =$C$1&"-"&$A15&"-"&D$2 -> БВ-0,45-РП | E15: =$C$1&"-"&$A15&"-"&E$2 -> БВ-0,45-Рх | F15: =$C$1&"-"&$A15&"-"&F$2 -> БВ-0,45-хП | G15: =$G$1&"-"&$A15&"-"&G$2 -> БОВ-0,45-С | H15: =$G$1&"-"&$A15&"-"&H$2 -> БОВ-0,45-Т | I15: =$G$1&"-"&$A15&"-"&I$2 -> БОВ-0,45-Т-2(50%) | J15: =$G$1&"-"&$A15&"-"&J$2 -> БОВ-0,45-Т-2(75%) | K15: =$G$1&"-"&$A15&"-"&K$2 -> БОВ-0,45-Т-2(100%) | L15: =$L$1&"-"&$A15 -> БГ-0,45 | M15: =$L$1&"-"&M$2&"-"&$A15&"/"&$A15 -> БГ-С-0,45/0,45 | N15: =$L$1&"-"&N$2&"-"&$A15&"/"&$A15 -> БГ-П-0,45/0,45 | O15: =$O$1&"-"&$A15 -> БОВГ-0,45 | P15: =$O$1&"-"&P$2&"-"&$A15&"/"&$A15 -> БОВГ-С-0,45/0,45 | Q15: =$O$1&"-"&Q$2&"-"&$A15&"/"&$A15 -> БОВГ-П-0,45/0,45
A16: 0,05 | C16: =$C$1&"-"&$A16&"-"&C$2 -> БВ-0,05-xx | D16: =$C$1&"-"&$A16&"-"&D$2 -> БВ-0,05-РП | E16: =$C$1&"-"&$A16&"-"&E$2 -> БВ-0,05-Рх | F16: =$C$1&"-"&$A16&"-"&F$2 -> БВ-0,05-хП | G16: =$G$1&"-"&$A16&"-"&G$2 -> БОВ-0,05-С | H16: =$G$1&"-"&$A16&"-"&H$2 -> БОВ-0,05-Т | I16: =$G$1&"-"&$A16&"-"&I$2 -> БОВ-0,05-Т-2(50%) | J16: =$G$1&"-"&$A16&"-"&J$2 -> БОВ-0,05-Т-2(75%) | K16: =$G$1&"-"&$A16&"-"&K$2 -> БОВ-0,05-Т-2(100%) | L16: =$L$1&"-"&$A16 -> БГ-0,05 | M16: =$L$1&"-"&M$2&"-"&$A16&"/"&$A16 -> БГ-С-0,05/0,05 | N16: =$L$1&"-"&N$2&"-"&$A16&"/"&$A16 -> БГ-П-0,05/0,05 | O16: =$O$1&"-"&$A16 -> БОВГ-0,05 | P16: =$O$1&"-"&P$2&"-"&$A16&"/"&$A16 -> БОВГ-С-0,05/0,05 | Q16: =$O$1&"-"&Q$2&"-"&$A16&"/"&$A16 -> БОВГ-П-0,05/0,05
A17: 0.55 | C17: =$C$1&"-"&$A17&"-"&C$2 -> БВ-0,55-xx | D17: =$C$1&"-"&$A17&"-"&D$2 -> БВ-0,55-РП | E17: =$C$1&"-"&$A17&"-"&E$2 -> БВ-0,55-Рх | F17: =$C$1&"-"&$A17&"-"&F$2 -> БВ-0,55-хП | G17: =$G$1&"-"&$A17&"-"&G$2 -> БОВ-0,55-С | H17: =$G$1&"-"&$A17&"-"&H$2 -> БОВ-0,55-Т | I17: =$G$1&"-"&$A17&"-"&I$2 -> БОВ-0,55-Т-2(50%) | J17: =$G$1&"-"&$A17&"-"&J$2 -> БОВ-0,55-Т-2(75%) | K17: =$G$1&"-"&$A17&"-"&K$2 -> БОВ-0,55-Т-2(100%) | L17: =$L$1&"-"&$A17 -> БГ-0,55 | M17: =$L$1&"-"&M$2&"-"&$A17&"/"&$A17 -> БГ-С-0,55/0,55 | N17: =$L$1&"-"&N$2&"-"&$A17&"/"&$A17 -> БГ-П-0,55/0,55 | O17: =$O$1&"-"&$A17 -> БОВГ-0,55 | P17: =$O$1&"-"&P$2&"-"&$A17&"/"&$A17 -> БОВГ-С-0,55/0,55 | Q17: =$O$1&"-"&Q$2&"-"&$A17&"/"&$A17 -> БОВГ-П-0,55/0,55
A18: 0,06 | C18: =$C$1&"-"&$A18&"-"&C$2 -> БВ-0,06-xx | D18: =$C$1&"-"&$A18&"-"&D$2 -> БВ-0,06-РП | E18: =$C$1&"-"&$A18&"-"&E$2 -> БВ-0,06-Рх | F18: =$C$1&"-"&$A18&"-"&F$2 -> БВ-0,06-хП | G18: =$G$1&"-"&$A18&"-"&G$2 -> БОВ-0,06-С | H18: =$G$1&"-"&$A18&"-"&H$2 -> БОВ-0,06-Т | I18: =$G$1&"-"&$A18&"-"&I$2 -> БОВ-0,06-Т-2(50%) | J18: =$G$1&"-"&$A18&"-"&J$2 -> БОВ-0,06-Т-2(75%) | K18: =$G$1&"-"&$A18&"-"&K$2 -> БОВ-0,06-Т-2(100%) | L18: =$L$1&"-"&$A18 -> БГ-0,06 | M18: =$L$1&"-"&M$2&"-"&$A18&"/"&$A18 -> БГ-С-0,06/0,06 | N18: =$L$1&"-"&N$2&"-"&$A18&"/"&$A18 -> БГ-П-0,06/0,06 | O18: =$O$1&"-"&$A18 -> БОВГ-0,06 | P18: =$O$1&"-"&P$2&"-"&$A18&"/"&$A18 -> БОВГ-С-0,06/0,06 | Q18: =$O$1&"-"&Q$2&"-"&$A18&"/"&$A18 -> БОВГ-П-0,06/0,06
A19: 0.65 | C19: =$C$1&"-"&$A19&"-"&C$2 -> БВ-0,65-xx | D19: =$C$1&"-"&$A19&"-"&D$2 -> БВ-0,65-РП | E19: =$C$1&"-"&$A19&"-"&E$2 -> БВ-0,65-Рх | F19: =$C$1&"-"&$A19&"-"&F$2 -> БВ-0,65-хП | G19: =$G$1&"-"&$A19&"-"&G$2 -> БОВ-0,65-С | H19: =$G$1&"-"&$A19&"-"&H$2 -> БОВ-0,65-Т | I19: =$G$1&"-"&$A19&"-"&I$2 -> БОВ-0,65-Т-2(50%) | J19: =$G$1&"-"&$A19&"-"&J$2 -> БОВ-0,65-Т-2(75%) | K19: =$G$1&"-"&$A19&"-"&K$2 -> БОВ-0,65-Т-2(100%) | L19: =$L$1&"-"&$A19 -> БГ-0,65 | M19: =$L$1&"-"&M$2&"-"&$A19&"/"&$A19 -> БГ-С-0,65/0,65 | N19: =$L$1&"-"&N$2&"-"&$A19&"/"&$A19 -> БГ-П-0,65/0,65 | O19: =$O$1&"-"&$A19 -> БОВГ-0,65 | P19: =$O$1&"-"&P$2&"-"&$A19&"/"&$A19 -> БОВГ-С-0,65/0,65 | Q19: =$O$1&"-"&Q$2&"-"&$A19&"/"&$A19 -> БОВГ-П-0,65/0,65
A20: 0,07 | C20: =$C$1&"-"&$A20&"-"&C$2 -> БВ-0,07-xx | D20: =$C$1&"-"&$A20&"-"&D$2 -> БВ-0,07-РП | E20: =$C$1&"-"&$A20&"-"&E$2 -> БВ-0,07-Рх | F20: =$C$1&"-"&$A20&"-"&F$2 -> БВ-0,07-хП | G20: =$G$1&"-"&$A20&"-"&G$2 -> БОВ-0,07-С | H20: =$G$1&"-"&$A20&"-"&H$2 -> БОВ-0,07-Т | I20: =$G$1&"-"&$A20&"-"&I$2 -> БОВ-0,07-Т-2(50%) | J20: =$G$1&"-"&$A20&"-"&J$2 -> БОВ-0,07-Т-2(75%) | K20: =$G$1&"-"&$A20&"-"&K$2 -> БОВ-0,07-Т-2(100%) | L20: =$L$1&"-"&$A20 -> БГ-0,07 | M20: =$L$1&"-"&M$2&"-"&$A20&"/"&$A20 -> БГ-С-0,07/0,07 | N20: =$L$1&"-"&N$2&"-"&$A20&"/"&$A20 -> БГ-П-0,07/0,07 | O20: =$O$1&"-"&$A20 -> БОВГ-0,07 | P20: =$O$1&"-"&P$2&"-"&$A20&"/"&$A20 -> БОВГ-С-0,07/0,07 | Q20: =$O$1&"-"&Q$2&"-"&$A20&"/"&$A20 -> БОВГ-П-0,07/0,07
A21: 0.75 | C21: =$C$1&"-"&$A21&"-"&C$2 -> БВ-0,75-xx | D21: =$C$1&"-"&$A21&"-"&D$2 -> БВ-0,75-РП | E21: =$C$1&"-"&$A21&"-"&E$2 -> БВ-0,75-Рх | F21: =$C$1&"-"&$A21&"-"&F$2 -> БВ-0,75-хП | G21: =$G$1&"-"&$A21&"-"&G$2 -> БОВ-0,75-С | H21: =$G$1&"-"&$A21&"-"&H$2 -> БОВ-0,75-Т | I21: =$G$1&"-"&$A21&"-"&I$2 -> БОВ-0,75-Т-2(50%) | J21: =$G$1&"-"&$A21&"-"&J$2 -> БОВ-0,75-Т-2(75%) | K21: =$G$1&"-"&$A21&"-"&K$2 -> БОВ-0,75-Т-2(100%) | L21: =$L$1&"-"&$A21 -> БГ-0,75 | M21: =$L$1&"-"&M$2&"-"&$A21&"/"&$A21 -> БГ-С-0,75/0,75 | N21: =$L$1&"-"&N$2&"-"&$A21&"/"&$A21 -> БГ-П-0,75/0,75 | O21: =$O$1&"-"&$A21 -> БОВГ-0,75 | P21: =$O$1&"-"&P$2&"-"&$A21&"/"&$A21 -> БОВГ-С-0,75/0,75 | Q21: =$O$1&"-"&Q$2&"-"&$A21&"/"&$A21 -> БОВГ-П-0,75/0,75
A22: 0,08 | C22: =$C$1&"-"&$A22&"-"&C$2 -> БВ-0,08-xx | D22: =$C$1&"-"&$A22&"-"&D$2 -> БВ-0,08-РП | E22: =$C$1&"-"&$A22&"-"&E$2 -> БВ-0,08-Рх | F22: =$C$1&"-"&$A22&"-"&F$2 -> БВ-0,08-хП | G22: =$G$1&"-"&$A22&"-"&G$2 -> БОВ-0,08-С | H22: =$G$1&"-"&$A22&"-"&H$2 -> БОВ-0,08-Т | I22: =$G$1&"-"&$A22&"-"&I$2 -> БОВ-0,08-Т-2(50%) | J22: =$G$1&"-"&$A22&"-"&J$2 -> БОВ-0,08-Т-2(75%) | K22: =$G$1&"-"&$A22&"-"&K$2 -> БОВ-0,08-Т-2(100%) | L22: =$L$1&"-"&$A22 -> БГ-0,08 | M22: =$L$1&"-"&M$2&"-"&$A22&"/"&$A22 -> БГ-С-0,08/0,08 | N22: =$L$1&"-"&N$2&"-"&$A22&"/"&$A22 -> БГ-П-0,08/0,08 | O22: =$O$1&"-"&$A22 -> БОВГ-0,08 | P22: =$O$1&"-"&P$2&"-"&$A22&"/"&$A22 -> БОВГ-С-0,08/0,08 | Q22: =$O$1&"-"&Q$2&"-"&$A22&"/"&$A22 -> БОВГ-П-0,08/0,08
A23: 0.85 | C23: =$C$1&"-"&$A23&"-"&C$2 -> БВ-0,85-xx | D23: =$C$1&"-"&$A23&"-"&D$2 -> БВ-0,85-РП | E23: =$C$1&"-"&$A23&"-"&E$2 -> БВ-0,85-Рх | F23: =$C$1&"-"&$A23&"-"&F$2 -> БВ-0,85-хП | G23: =$G$1&"-"&$A23&"-"&G$2 -> БОВ-0,85-С | H23: =$G$1&"-"&$A23&"-"&H$2 -> БОВ-0,85-Т | I23: =$G$1&"-"&$A23&"-"&I$2 -> БОВ-0,85-Т-2(50%) | J23: =$G$1&"-"&$A23&"-"&J$2 -> БОВ-0,85-Т-2(75%) | K23: =$G$1&"-"&$A23&"-"&K$2 -> БОВ-0,85-Т-2(100%) | L23: =$L$1&"-"&$A23 -> БГ-0,85 | M23: =$L$1&"-"&M$2&"-"&$A23&"/"&$A23 -> БГ-С-0,85/0,85 | N23: =$L$1&"-"&N$2&"-"&$A23&"/"&$A23 -> БГ-П-0,85/0,85 | O23: =$O$1&"-"&$A23 -> БОВГ-0,85 | P23: =$O$1&"-"&P$2&"-"&$A23&"/"&$A23 -> БОВГ-С-0,85/0,85 | Q23: =$O$1&"-"&Q$2&"-"&$A23&"/"&$A23 -> БОВГ-П-0,85/0,85
A24: 0,09 | C24: =$C$1&"-"&$A24&"-"&C$2 -> БВ-0,09-xx | D24: =$C$1&"-"&$A24&"-"&D$2 -> БВ-0,09-РП | E24: =$C$1&"-"&$A24&"-"&E$2 -> БВ-0,09-Рх | F24: =$C$1&"-"&$A24&"-"&F$2 -> БВ-0,09-хП | G24: =$G$1&"-"&$A24&"-"&G$2 -> БОВ-0,09-С | H24: =$G$1&"-"&$A24&"-"&H$2 -> БОВ-0,09-Т | I24: =$G$1&"-"&$A24&"-"&I$2 -> БОВ-0,09-Т-2(50%) | J24: =$G$1&"-"&$A24&"-"&J$2 -> БОВ-0,09-Т-2(75%) | K24: =$G$1&"-"&$A24&"-"&K$2 -> БОВ-0,09-Т-2(100%) | L24: =$L$1&"-"&$A24 -> БГ-0,09 | M24: =$L$1&"-"&M$2&"-"&$A24&"/"&$A24 -> БГ-С-0,09/0,09 | N24: =$L$1&"-"&N$2&"-"&$A24&"/"&$A24 -> БГ-П-0,09/0,09 | O24: =$O$1&"-"&$A24 -> БОВГ-0,09 | P24: =$O$1&"-"&P$2&"-"&$A24&"/"&$A24 -> БОВГ-С-0,09/0,09 | Q24: =$O$1&"-"&Q$2&"-"&$A24&"/"&$A24 -> БОВГ-П-0,09/0,09
A25: 0.95 | C25: =$C$1&"-"&$A25&"-"&C$2 -> БВ-0,95-xx | D25: =$C$1&"-"&$A25&"-"&D$2 -> БВ-0,95-РП | E25: =$C$1&"-"&$A25&"-"&E$2 -> БВ-0,95-Рх | F25: =$C$1&"-"&$A25&"-"&F$2 -> БВ-0,95-хП | G25: =$G$1&"-"&$A25&"-"&G$2 -> БОВ-0,95-С | H25: =$G$1&"-"&$A25&"-"&H$2 -> БОВ-0,95-Т | I25: =$G$1&"-"&$A25&"-"&I$2 -> БОВ-0,95-Т-2(50%) | J25: =$G$1&"-"&$A25&"-"&J$2 -> БОВ-0,95-Т-2(75%) | K25: =$G$1&"-"&$A25&"-"&K$2 -> БОВ-0,95-Т-2(100%) | L25: =$L$1&"-"&$A25 -> БГ-0,95 | M25: =$L$1&"-"&M$2&"-"&$A25&"/"&$A25 -> БГ-С-0,95/0,95 | N25: =$L$1&"-"&N$2&"-"&$A25&"/"&$A25 -> БГ-П-0,95/0,95 | O25: =$O$1&"-"&$A25 -> БОВГ-0,95 | P25: =$O$1&"-"&P$2&"-"&$A25&"/"&$A25 -> БОВГ-С-0,95/0,95 | Q25: =$O$1&"-"&Q$2&"-"&$A25&"/"&$A25 -> БОВГ-П-0,95/0,95
A26: 1,0 | C26: =$C$1&"-"&$A26&"-"&C$2 -> БВ-1,0-xx | D26: =$C$1&"-"&$A26&"-"&D$2 -> БВ-1,0-РП | E26: =$C$1&"-"&$A26&"-"&E$2 -> БВ-1,0-Рх | F26: =$C$1&"-"&$A26&"-"&F$2 -> БВ-1,0-хП | G26: =$G$1&"-"&$A26&"-"&G$2 -> БОВ-1,0-С | H26: =$G$1&"-"&$A26&"-"&H$2 -> БОВ-1,0-Т | I26: =$G$1&"-"&$A26&"-"&I$2 -> БОВ-1,0-Т-2(50%) | J26: =$G$1&"-"&$A26&"-"&J$2 -> БОВ-1,0-Т-2(75%) | K26: =$G$1&"-"&$A26&"-"&K$2 -> БОВ-1,0-Т-2(100%) | L26: =$L$1&"-"&$A26 -> БГ-1,0 | M26: =$L$1&"-"&M$2&"-"&$A26&"/"&$A26 -> БГ-С-1,0/1,0 | N26: =$L$1&"-"&N$2&"-"&$A26&"/"&$A26 -> БГ-П-1,0/1,0 | O26: =$O$1&"-"&$A26 -> БОВГ-1,0 | P26: =$O$1&"-"&P$2&"-"&$A26&"/"&$A26 -> БОВГ-С-1,0/1,0 | Q26: =$O$1&"-"&Q$2&"-"&$A26&"/"&$A26 -> БОВГ-П-1,0/1,0
A27: 1.1 | C27: =$C$1&"-"&$A27&"-"&C$2 -> БВ-1,1-xx | D27: =$C$1&"-"&$A27&"-"&D$2 -> БВ-1,1-РП | E27: =$C$1&"-"&$A27&"-"&E$2 -> БВ-1,1-Рх | F27: =$C$1&"-"&$A27&"-"&F$2 -> БВ-1,1-хП | G27: =$G$1&"-"&$A27&"-"&G$2 -> БОВ-1,1-С | H27: =$G$1&"-"&$A27&"-"&H$2 -> БОВ-1,1-Т | I27: =$G$1&"-"&$A27&"-"&I$2 -> БОВ-1,1-Т-2(50%) | J27: =$G$1&"-"&$A27&"-"&J$2 -> БОВ-1,1-Т-2(75%) | K27: =$G$1&"-"&$A27&"-"&K$2 -> БОВ-1,1-Т-2(100%) | L27: =$L$1&"-"&$A27 -> БГ-1,1 | M27: =$L$1&"-"&M$2&"-"&$A27&"/"&$A27 -> БГ-С-1,1/1,1 | N27: =$L$1&"-"&N$2&"-"&$A27&"/"&$A27 -> БГ-П-1,1/1,1 | O27: =$O$1&"-"&$A27 -> БОВГ-1,1 | P27: =$O$1&"-"&P$2&"-"&$A27&"/"&$A27 -> БОВГ-С-1,1/1,1 | Q27: =$O$1&"-"&Q$2&"-"&$A27&"/"&$A27 -> БОВГ-П-1,1/1,1
A28: 1.2 | C28: =$C$1&"-"&$A28&"-"&C$2 -> БВ-1,2-xx | D28: =$C$1&"-"&$A28&"-"&D$2 -> БВ-1,2-РП | E28: =$C$1&"-"&$A28&"-"&E$2 -> БВ-1,2-Рх | F28: =$C$1&"-"&$A28&"-"&F$2 -> БВ-1,2-хП | G28: =$G$1&"-"&$A28&"-"&G$2 -> БОВ-1,2-С | H28: =$G$1&"-"&$A28&"-"&H$2 -> БОВ-1,2-Т | I28: =$G$1&"-"&$A28&"-"&I$2 -> БОВ-1,2-Т-2(50%) | J28: =$G$1&"-"&$A28&"-"&J$2 -> БОВ-1,2-Т-2(75%) | K28: =$G$1&"-"&$A28&"-"&K$2 -> БОВ-1,2-Т-2(100%) | L28: =$L$1&"-"&$A28 -> БГ-1,2 | M28: =$L$1&"-"&M$2&"-"&$A28&"/"&$A28 -> БГ-С-1,2/1,2 | N28: =$L$1&"-"&N$2&"-"&$A28&"/"&$A28 -> БГ-П-1,2/1,2 | O28: =$O$1&"-"&$A28 -> БОВГ-1,2 | P28: =$O$1&"-"&P$2&"-"&$A28&"/"&$A28 -> БОВГ-С-1,2/1,2 | Q28: =$O$1&"-"&Q$2&"-"&$A28&"/"&$A28 -> БОВГ-П-1,2/1,2
A29: 1.3 | C29: =$C$1&"-"&$A29&"-"&C$2 -> БВ-1,3-xx | D29: =$C$1&"-"&$A29&"-"&D$2 -> БВ-1,3-РП | E29: =$C$1&"-"&$A29&"-"&E$2 -> БВ-1,3-Рх | F29: =$C$1&"-"&$A29&"-"&F$2 -> БВ-1,3-хП | G29: =$G$1&"-"&$A29&"-"&G$2 -> БОВ-1,3-С | H29: =$G$1&"-"&$A29&"-"&H$2 -> БОВ-1,3-Т | I29: =$G$1&"-"&$A29&"-"&I$2 -> БОВ-1,3-Т-2(50%) | J29: =$G$1&"-"&$A29&"-"&J$2 -> БОВ-1,3-Т-2(75%) | K29: =$G$1&"-"&$A29&"-"&K$2 -> БОВ-1,3-Т-2(100%) | L29: =$L$1&"-"&$A29 -> БГ-1,3 | M29: =$L$1&"-"&M$2&"-"&$A29&"/"&$A29 -> БГ-С-1,3/1,3 | N29: =$L$1&"-"&N$2&"-"&$A29&"/"&$A29 -> БГ-П-1,3/1,3 | O29: =$O$1&"-"&$A29 -> БОВГ-1,3 | P29: =$O$1&"-"&P$2&"-"&$A29&"/"&$A29 -> БОВГ-С-1,3/1,3 | Q29: =$O$1&"-"&Q$2&"-"&$A29&"/"&$A29 -> БОВГ-П-1,3/1,3
A30: 1.4 | C30: =$C$1&"-"&$A30&"-"&C$2 -> БВ-1,4-xx | D30: =$C$1&"-"&$A30&"-"&D$2 -> БВ-1,4-РП | E30: =$C$1&"-"&$A30&"-"&E$2 -> БВ-1,4-Рх | F30: =$C$1&"-"&$A30&"-"&F$2 -> БВ-1,4-хП | G30: =$G$1&"-"&$A30&"-"&G$2 -> БОВ-1,4-С | H30: =$G$1&"-"&$A30&"-"&H$2 -> БОВ-1,4-Т | I30: =$G$1&"-"&$A30&"-"&I$2 -> БОВ-1,4-Т-2(50%) | J30: =$G$1&"-"&$A30&"-"&J$2 -> БОВ-1,4-Т-2(75%) | K30: =$G$1&"-"&$A30&"-"&K$2 -> БОВ-1,4-Т-2(100%) | L30: =$L$1&"-"&$A30 -> БГ-1,4 | M30: =$L$1&"-"&M$2&"-"&$A30&"/"&$A30 -> БГ-С-1,4/1,4 | N30: =$L$1&"-"&N$2&"-"&$A30&"/"&$A30 -> БГ-П-1,4/1,4 | O30: =$O$1&"-"&$A30 -> БОВГ-1,4 | P30: =$O$1&"-"&P$2&"-"&$A30&"/"&$A30 -> БОВГ-С-1,4/1,4 | Q30: =$O$1&"-"&Q$2&"-"&$A30&"/"&$A30 -> БОВГ-П-1,4/1,4
A31: 1.5 | C31: =$C$1&"-"&$A31&"-"&C$2 -> БВ-1,5-xx | D31: =$C$1&"-"&$A31&"-"&D$2 -> БВ-1,5-РП | E31: =$C$1&"-"&$A31&"-"&E$2 -> БВ-1,5-Рх | F31: =$C$1&"-"&$A31&"-"&F$2 -> БВ-1,5-хП | G31: =$G$1&"-"&$A31&"-"&G$2 -> БОВ-1,5-С | H31: =$G$1&"-"&$A31&"-"&H$2 -> БОВ-1,5-Т | I31: =$G$1&"-"&$A31&"-"&I$2 -> БОВ-1,5-Т-2(50%) | J31: =$G$1&"-"&$A31&"-"&J$2 -> БОВ-1,5-Т-2(75%) | K31: =$G$1&"-"&$A31&"-"&K$2 -> БОВ-1,5-Т-2(100%) | L31: =$L$1&"-"&$A31 -> БГ-1,5 | M31: =$L$1&"-"&M$2&"-"&$A31&"/"&$A31 -> БГ-С-1,5/1,5 | N31: =$L$1&"-"&N$2&"-"&$A31&"/"&$A31 -> БГ-П-1,5/1,5 | O31: =$O$1&"-"&$A31 -> БОВГ-1,5 | P31: =$O$1&"-"&P$2&"-"&$A31&"/"&$A31 -> БОВГ-С-1,5/1,5 | Q31: =$O$1&"-"&Q$2&"-"&$A31&"/"&$A31 -> БОВГ-П-1,5/1,5
A32: 1.6 | C32: =$C$1&"-"&$A32&"-"&C$2 -> БВ-1,6-xx | D32: =$C$1&"-"&$A32&"-"&D$2 -> БВ-1,6-РП | E32: =$C$1&"-"&$A32&"-"&E$2 -> БВ-1,6-Рх | F32: =$C$1&"-"&$A32&"-"&F$2 -> БВ-1,6-хП | G32: =$G$1&"-"&$A32&"-"&G$2 -> БОВ-1,6-С | H32: =$G$1&"-"&$A32&"-"&H$2 -> БОВ-1,6-Т | I32: =$G$1&"-"&$A32&"-"&I$2 -> БОВ-1,6-Т-2(50%) | J32: =$G$1&"-"&$A32&"-"&J$2 -> БОВ-1,6-Т-2(75%) | K32: =$G$1&"-"&$A32&"-"&K$2 -> БОВ-1,6-Т-2(100%) | L32: =$L$1&"-"&$A32 -> БГ-1,6 | M32: =$L$1&"-"&M$2&"-"&$A32&"/"&$A32 -> БГ-С-1,6/1,6 | N32: =$L$1&"-"&N$2&"-"&$A32&"/"&$A32 -> БГ-П-1,6/1,6 | O32: =$O$1&"-"&$A32 -> БОВГ-1,6 | P32: =$O$1&"-"&P$2&"-"&$A32&"/"&$A32 -> БОВГ-С-1,6/1,6 | Q32: =$O$1&"-"&Q$2&"-"&$A32&"/"&$A32 -> БОВГ-П-1,6/1,6
A33: 1.7 | C33: =$C$1&"-"&$A33&"-"&C$2 -> БВ-1,7-xx | D33: =$C$1&"-"&$A33&"-"&D$2 -> БВ-1,7-РП | E33: =$C$1&"-"&$A33&"-"&E$2 -> БВ-1,7-Рх | F33: =$C$1&"-"&$A33&"-"&F$2 -> БВ-1,7-хП | G33: =$G$1&"-"&$A33&"-"&G$2 -> БОВ-1,7-С | H33: =$G$1&"-"&$A33&"-"&H$2 -> БОВ-1,7-Т | I33: =$G$1&"-"&$A33&"-"&I$2 -> БОВ-1,7-Т-2(50%) | J33: =$G$1&"-"&$A33&"-"&J$2 -> БОВ-1,7-Т-2(75%) | K33: =$G$1&"-"&$A33&"-"&K$2 -> БОВ-1,7-Т-2(100%) | L33: =$L$1&"-"&$A33 -> БГ-1,7 | M33: =$L$1&"-"&M$2&"-"&$A33&"/"&$A33 -> БГ-С-1,7/1,7 | N33: =$L$1&"-"&N$2&"-"&$A33&"/"&$A33 -> БГ-П-1,7/1,7 | O33: =$O$1&"-"&$A33 -> БОВГ-1,7 | P33: =$O$1&"-"&P$2&"-"&$A33&"/"&$A33 -> БОВГ-С-1,7/1,7 | Q33: =$O$1&"-"&Q$2&"-"&$A33&"/"&$A33 -> БОВГ-П-1,7/1,7
A34: 1.8 | C34: =$C$1&"-"&$A34&"-"&C$2 -> БВ-1,8-xx | D34: =$C$1&"-"&$A34&"-"&D$2 -> БВ-1,8-РП | E34: =$C$1&"-"&$A34&"-"&E$2 -> БВ-1,8-Рх | F34: =$C$1&"-"&$A34&"-"&F$2 -> БВ-1,8-хП | G34: =$G$1&"-"&$A34&"-"&G$2 -> БОВ-1,8-С | H34: =$G$1&"-"&$A34&"-"&H$2 -> БОВ-1,8-Т | I34: =$G$1&"-"&$A34&"-"&I$2 -> БОВ-1,8-Т-2(50%) | J34: =$G$1&"-"&$A34&"-"&J$2 -> БОВ-1,8-Т-2(75%) | K34: =$G$1&"-"&$A34&"-"&K$2 -> БОВ-1,8-Т-2(100%) | L34: =$L$1&"-"&$A34 -> БГ-1,8 | M34: =$L$1&"-"&M$2&"-"&$A34&"/"&$A34 -> БГ-С-1,8/1,8 | N34: =$L$1&"-"&N$2&"-"&$A34&"/"&$A34 -> БГ-П-1,8/1,8 | O34: =$O$1&"-"&$A34 -> БОВГ-1,8 | P34: =$O$1&"-"&P$2&"-"&$A34&"/"&$A34 -> БОВГ-С-1,8/1,8 | Q34: =$O$1&"-"&Q$2&"-"&$A34&"/"&$A34 -> БОВГ-П-1,8/1,8
A35: 1.9 | C35: =$C$1&"-"&$A35&"-"&C$2 -> БВ-1,9-xx | D35: =$C$1&"-"&$A35&"-"&D$2 -> БВ-1,9-РП | E35: =$C$1&"-"&$A35&"-"&E$2 -> БВ-1,9-Рх | F35: =$C$1&"-"&$A35&"-"&F$2 -> БВ-1,9-хП | G35: =$G$1&"-"&$A35&"-"&G$2 -> БОВ-1,9-С | H35: =$G$1&"-"&$A35&"-"&H$2 -> БОВ-1,9-Т | I35: =$G$1&"-"&$A35&"-"&I$2 -> БОВ-1,9-Т-2(50%) | J35: =$G$1&"-"&$A35&"-"&J$2 -> БОВ-1,9-Т-2(75%) | K35: =$G$1&"-"&$A35&"-"&K$2 -> БОВ-1,9-Т-2(100%) | L35: =$L$1&"-"&$A35 -> БГ-1,9 | M35: =$L$1&"-"&M$2&"-"&$A35&"/"&$A35 -> БГ-С-1,9/1,9 | N35: =$L$1&"-"&N$2&"-"&$A35&"/"&$A35 -> БГ-П-1,9/1,9 | O35: =$O$1&"-"&$A35 -> БОВГ-1,9 | P35: =$O$1&"-"&P$2&"-"&$A35&"/"&$A35 -> БОВГ-С-1,9/1,9 | Q35: =$O$1&"-"&Q$2&"-"&$A35&"/"&$A35 -> БОВГ-П-1,9/1,9
A36: 2,0 | C36: =$C$1&"-"&$A36&"-"&C$2 -> БВ-2,0-xx | D36: =$C$1&"-"&$A36&"-"&D$2 -> БВ-2,0-РП | E36: =$C$1&"-"&$A36&"-"&E$2 -> БВ-2,0-Рх | F36: =$C$1&"-"&$A36&"-"&F$2 -> БВ-2,0-хП | G36: =$G$1&"-"&$A36&"-"&G$2 -> БОВ-2,0-С | H36: =$G$1&"-"&$A36&"-"&H$2 -> БОВ-2,0-Т | I36: =$G$1&"-"&$A36&"-"&I$2 -> БОВ-2,0-Т-2(50%) | J36: =$G$1&"-"&$A36&"-"&J$2 -> БОВ-2,0-Т-2(75%) | K36: =$G$1&"-"&$A36&"-"&K$2 -> БОВ-2,0-Т-2(100%) | L36: =$L$1&"-"&$A36 -> БГ-2,0 | M36: =$L$1&"-"&M$2&"-"&$A36&"/"&$A36 -> БГ-С-2,0/2,0 | N36: =$L$1&"-"&N$2&"-"&$A36&"/"&$A36 -> БГ-П-2,0/2,0 | O36: =$O$1&"-"&$A36 -> БОВГ-2,0 | P36: =$O$1&"-"&P$2&"-"&$A36&"/"&$A36 -> БОВГ-С-2,0/2,0 | Q36: =$O$1&"-"&Q$2&"-"&$A36&"/"&$A36 -> БОВГ-П-2,0/2,0
A37: 2.1 | C37: =$C$1&"-"&$A37&"-"&C$2 -> БВ-2,1-xx | D37: =$C$1&"-"&$A37&"-"&D$2 -> БВ-2,1-РП | E37: =$C$1&"-"&$A37&"-"&E$2 -> БВ-2,1-Рх | F37: =$C$1&"-"&$A37&"-"&F$2 -> БВ-2,1-хП | G37: =$G$1&"-"&$A37&"-"&G$2 -> БОВ-2,1-С | H37: =$G$1&"-"&$A37&"-"&H$2 -> БОВ-2,1-Т | I37: =$G$1&"-"&$A37&"-"&I$2 -> БОВ-2,1-Т-2(50%) | J37: =$G$1&"-"&$A37&"-"&J$2 -> БОВ-2,1-Т-2(75%) | K37: =$G$1&"-"&$A37&"-"&K$2 -> БОВ-2,1-Т-2(100%) | L37: =$L$1&"-"&$A37 -> БГ-2,1 | M37: =$L$1&"-"&M$2&"-"&$A37&"/"&$A37 -> БГ-С-2,1/2,1 | N37: =$L$1&"-"&N$2&"-"&$A37&"/"&$A37 -> БГ-П-2,1/2,1 | O37: =$O$1&"-"&$A37 -> БОВГ-2,1 | P37: =$O$1&"-"&P$2&"-"&$A37&"/"&$A37 -> БОВГ-С-2,1/2,1 | Q37: =$O$1&"-"&Q$2&"-"&$A37&"/"&$A37 -> БОВГ-П-2,1/2,1
A38: 2.2 | C38: =$C$1&"-"&$A38&"-"&C$2 -> БВ-2,2-xx | D38: =$C$1&"-"&$A38&"-"&D$2 -> БВ-2,2-РП | E38: =$C$1&"-"&$A38&"-"&E$2 -> БВ-2,2-Рх | F38: =$C$1&"-"&$A38&"-"&F$2 -> БВ-2,2-хП | G38: =$G$1&"-"&$A38&"-"&G$2 -> БОВ-2,2-С | H38: =$G$1&"-"&$A38&"-"&H$2 -> БОВ-2,2-Т | I38: =$G$1&"-"&$A38&"-"&I$2 -> БОВ-2,2-Т-2(50%) | J38: =$G$1&"-"&$A38&"-"&J$2 -> БОВ-2,2-Т-2(75%) | K38: =$G$1&"-"&$A38&"-"&K$2 -> БОВ-2,2-Т-2(100%) | L38: =$L$1&"-"&$A38 -> БГ-2,2 | M38: =$L$1&"-"&M$2&"-"&$A38&"/"&$A38 -> БГ-С-2,2/2,2 | N38: =$L$1&"-"&N$2&"-"&$A38&"/"&$A38 -> БГ-П-2,2/2,2 | O38: =$O$1&"-"&$A38 -> БОВГ-2,2 | P38: =$O$1&"-"&P$2&"-"&$A38&"/"&$A38 -> БОВГ-С-2,2/2,2 | Q38: =$O$1&"-"&Q$2&"-"&$A38&"/"&$A38 -> БОВГ-П-2,2/2,2
A39: 2.3 | C39: =$C$1&"-"&$A39&"-"&C$2 -> БВ-2,3-xx | D39: =$C$1&"-"&$A39&"-"&D$2 -> БВ-2,3-РП | E39: =$C$1&"-"&$A39&"-"&E$2 -> БВ-2,3-Рх | F39: =$C$1&"-"&$A39&"-"&F$2 -> БВ-2,3-хП | G39: =$G$1&"-"&$A39&"-"&G$2 -> БОВ-2,3-С | H39: =$G$1&"-"&$A39&"-"&H$2 -> БОВ-2,3-Т | I39: =$G$1&"-"&$A39&"-"&I$2 -> БОВ-2,3-Т-2(50%) | J39: =$G$1&"-"&$A39&"-"&J$2 -> БОВ-2,3-Т-2(75%) | K39: =$G$1&"-"&$A39&"-"&K$2 -> БОВ-2,3-Т-2(100%) | L39: =$L$1&"-"&$A39 -> БГ-2,3 | M39: =$L$1&"-"&M$2&"-"&$A39&"/"&$A39 -> БГ-С-2,3/2,3 | N39: =$L$1&"-"&N$2&"-"&$A39&"/"&$A39 -> БГ-П-2,3/2,3 | O39: =$O$1&"-"&$A39 -> БОВГ-2,3 | P39: =$O$1&"-"&P$2&"-"&$A39&"/"&$A39 -> БОВГ-С-2,3/2,3 | Q39: =$O$1&"-"&Q$2&"-"&$A39&"/"&$A39 -> БОВГ-П-2,3/2,3
A40: 2.4 | C40: =$C$1&"-"&$A40&"-"&C$2 -> БВ-2,4-xx | D40: =$C$1&"-"&$A40&"-"&D$2 -> БВ-2,4-РП | E40: =$C$1&"-"&$A40&"-"&E$2 -> БВ-2,4-Рх | F40: =$C$1&"-"&$A40&"-"&F$2 -> БВ-2,4-хП | G40: =$G$1&"-"&$A40&"-"&G$2 -> БОВ-2,4-С | H40: =$G$1&"-"&$A40&"-"&H$2 -> БОВ-2,4-Т | I40: =$G$1&"-"&$A40&"-"&I$2 -> БОВ-2,4-Т-2(50%) | J40: =$G$1&"-"&$A40&"-"&J$2 -> БОВ-2,4-Т-2(75%) | K40: =$G$1&"-"&$A40&"-"&K$2 -> БОВ-2,4-Т-2(100%) | L40: =$L$1&"-"&$A40 -> БГ-2,4 | M40: =$L$1&"-"&M$2&"-"&$A40&"/"&$A40 -> БГ-С-2,4/2,4 | N40: =$L$1&"-"&N$2&"-"&$A40&"/"&$A40 -> БГ-П-2,4/2,4 | O40: =$O$1&"-"&$A40 -> БОВГ-2,4 | P40: =$O$1&"-"&P$2&"-"&$A40&"/"&$A40 -> БОВГ-С-2,4/2,4 | Q40: =$O$1&"-"&Q$2&"-"&$A40&"/"&$A40 -> БОВГ-П-2,4/2,4
...

Sheet Лист2
C1: 0.05 | D1: 0.06 | E1: 0.07 | F1: 0.08 | G1: 0.09 | H1: 0.1 | I1: 0.15 | J1: 0.2 | K1: 0.25 | L1: 0.3 | M1: 0.35 | N1: 0.4 | O1: 0.45 | P1: 0.5 | Q1: 0.55 | R1: 0.6 | S1: 0.65 | T1: 0.7 | U1: 0.75 | V1: 0.8 | W1: 0.85 | X1: 0.9 | Y1: 0.95 | Z1: 1 | AA1: 1.1 | AB1: 1.2 | AC1: 1.3 | AD1: 1.4 | AE1: 1.5 | AF1: 1.6 | AG1: 1.7 | AH1: 1.8 | AI1: 1.9 | AJ1: 2
B2: 0.05 | C2: =$B2/C$1 -> 1 | D2: =$B2/D$1 -> 0.83333333 | E2: =$B2/E$1 -> 0.71428571 | F2: =$B2/F$1 -> 0.625 | G2: =$B2/G$1 -> 0.55555556 | H2: =$B2/H$1 -> 0.5 | I2: =$B2/I$1 -> 0.33333333 | J2: =$B2/J$1 -> 0.25 | K2: =$B2/K$1 -> 0.2
B3: 0.06 | D3: =$B3/D$1 -> 1 | E3: =$B3/E$1 -> 0.85714286 | F3: =$B3/F$1 -> 0.75 | G3: =$B3/G$1 -> 0.66666667 | H3: =$B3/H$1 -> 0.6 | I3: =$B3/I$1 -> 0.4 | J3: =$B3/J$1 -> 0.3 | K3: =$B3/K$1 -> 0.24 | L3: =$B3/L$1 -> 0.2
B4: 0.07 | E4: =$B4/E$1 -> 1 | F4: =$B4/F$1 -> 0.875 | G4: =$B4/G$1 -> 0.77777778 | H4: =$B4/H$1 -> 0.7 | I4: =$B4/I$1 -> 0.46666667 | J4: =$B4/J$1 -> 0.35 | K4: =$B4/K$1 -> 0.28 | L4: =$B4/L$1 -> 0.23333333 | M4: =$B4/M$1 -> 0.2
B5: 0.08 | F5: =$B5/F$1 -> 1 | G5: =$B5/G$1 -> 0.88888889 | H5: =$B5/H$1 -> 0.8 | I5: =$B5/I$1 -> 0.53333333 | J5: =$B5/J$1 -> 0.4 | K5: =$B5/K$1 -> 0.32 | L5: =$B5/L$1 -> 0.26666667 | M5: =$B5/M$1 -> 0.22857143 | N5: =$B5/N$1 -> 0.2
B6: 0.09 | G6: =$B6/G$1 -> 1 | H6: =$B6/H$1 -> 0.9 | I6: =$B6/I$1 -> 0.6 | J6: =$B6/J$1 -> 0.45 | K6: =$B6/K$1 -> 0.36 | L6: =$B6/L$1 -> 0.3 | M6: =$B6/M$1 -> 0.25714286 | N6: =$B6/N$1 -> 0.225 | O6: =$B6/O$1 -> 0.2
B7: 0.1 | H7: =$B7/H$1 -> 1 | I7: =$B7/I$1 -> 0.66666667 | J7: =$B7/J$1 -> 0.5 | K7: =$B7/K$1 -> 0.4 | L7: =$B7/L$1 -> 0.33333333 | M7: =$B7/M$1 -> 0.28571429 | N7: =$B7/N$1 -> 0.25 | O7: =$B7/O$1 -> 0.22222222 | P7: =$B7/P$1 -> 0.2
B8: 0.15 | I8: =$B8/I$1 -> 1 | J8: =$B8/J$1 -> 0.75 | K8: =$B8/K$1 -> 0.6 | L8: =$B8/L$1 -> 0.5 | M8: =$B8/M$1 -> 0.42857143 | N8: =$B8/N$1 -> 0.375 | O8: =$B8/O$1 -> 0.33333333 | P8: =$B8/P$1 -> 0.3 | ... U8: =$B8/U$1 -> 0.2
B9: 0.2 | J9: =$B9/J$1 -> 1 | K9: =$B9/K$1 -> 0.8 | L9: =$B9/L$1 -> 0.66666667 | M9: =$B9/M$1 -> 0.57142857 | N9: =$B9/N$1 -> 0.5 | O9: =$B9/O$1 -> 0.44444444 | P9: =$B9/P$1 -> 0.4 | Q9: =$B9/Q$1 -> 0.36363636 | ... Z9: =$B9/Z$1 -> 0.2
B10: 0.25 | K10: =$B10/K$1 -> 1 | L10: =$B10/L$1 -> 0.83333333 | M10: =$B10/M$1 -> 0.71428571 | N10: =$B10/N$1 -> 0.625 | O10: =$B10/O$1 -> 0.55555556 | P10: =$B10/P$1 -> 0.5 | Q10: =$B10/Q$1 -> 0.45454545 | R10: =$B10/R$1 -> 0.41666667 | ... AB10: =$B10/AB$1 -> 0.20833333
B11: 0.3 | L11: =$B11/L$1 -> 1 | M11: =$B11/M$1 -> 0.85714286 | N11: =$B11/N$1 -> 0.75 | O11: =$B11/O$1 -> 0.66666667 | P11: =$B11/P$1 -> 0.6 | Q11: =$B11/Q$1 -> 0.54545455 | R11: =$B11/R$1 -> 0.5 | S11: =$B11/S$1 -> 0.46153846 | ... AE11: =$B11/AE$1 -> 0.2
B12: 0.35 | M12: =$B12/M$1 -> 1 | N12: =$B12/N$1 -> 0.875 | O12: =$B12/O$1 -> 0.77777778 | P12: =$B12/P$1 -> 0.7 | Q12: =$B12/Q$1 -> 0.63636364 | R12: =$B12/R$1 -> 0.58333333 | S12: =$B12/S$1 -> 0.53846154 | T12: =$B12/T$1 -> 0.5 | ... AG12: =$B12/AG$1 -> 0.20588235
B13: 0.4 | N13: =$B13/N$1 -> 1 | O13: =$B13/O$1 -> 0.88888889 | P13: =$B13/P$1 -> 0.8 | Q13: =$B13/Q$1 -> 0.72727273 | R13: =$B13/R$1 -> 0.66666667 | S13: =$B13/S$1 -> 0.61538462 | T13: =$B13/T$1 -> 0.57142857 | U13: =$B13/U$1 -> 0.53333333 | ... AJ13: =$B13/AJ$1 -> 0.2
B14: 0.45 | O14: =$B14/O$1 -> 1 | P14: =$B14/P$1 -> 0.9 | Q14: =$B14/Q$1 -> 0.81818182 | R14: =$B14/R$1 -> 0.75 | S14: =$B14/S$1 -> 0.69230769 | T14: =$B14/T$1 -> 0.64285714 | U14: =$B14/U$1 -> 0.6 | V14: =$B14/V$1 -> 0.5625 | ... AJ14: =$B14/AJ$1 -> 0.225
B15: 0.5 | P15: =$B15/P$1 -> 1 | Q15: =$B15/Q$1 -> 0.90909091 | R15: =$B15/R$1 -> 0.83333333 | S15: =$B15/S$1 -> 0.76923077 | T15: =$B15/T$1 -> 0.71428571 | U15: =$B15/U$1 -> 0.66666667 | V15: =$B15/V$1 -> 0.625 | W15: =$B15/W$1 -> 0.58823529 | ... AJ15: =$B15/AJ$1 -> 0.25
B16: 0.55 | Q16: =$B16/Q$1 -> 1 | R16: =$B16/R$1 -> 0.91666667 | S16: =$B16/S$1 -> 0.84615385 | T16: =$B16/T$1 -> 0.78571429 | U16: =$B16/U$1 -> 0.73333333 | V16: =$B16/V$1 -> 0.6875 | W16: =$B16/W$1 -> 0.64705882 | X16: =$B16/X$1 -> 0.61111111 | ... AJ16: =$B16/AJ$1 -> 0.275
B17: 0.6 | R17: =$B17/R$1 -> 1 | S17: =$B17/S$1 -> 0.92307692 | T17: =$B17/T$1 -> 0.85714286 | U17: =$B17/U$1 -> 0.8 | V17: =$B17/V$1 -> 0.75 | W17: =$B17/W$1 -> 0.70588235 | X17: =$B17/X$1 -> 0.66666667 | Y17: =$B17/Y$1 -> 0.63157895 | ... AJ17: =$B17/AJ$1 -> 0.3
B18: 0.65 | S18: =$B18/S$1 -> 1 | T18: =$B18/T$1 -> 0.92857143 | U18: =$B18/U$1 -> 0.86666667 | V18: =$B18/V$1 -> 0.8125 | W18: =$B18/W$1 -> 0.76470588 | X18: =$B18/X$1 -> 0.72222222 | Y18: =$B18/Y$1 -> 0.68421053 | Z18: =$B18/Z$1 -> 0.65 | ... AJ18: =$B18/AJ$1 -> 0.325
B19: 0.7 | T19: =$B19/T$1 -> 1 | U19: =$B19/U$1 -> 0.93333333 | V19: =$B19/V$1 -> 0.875 | W19: =$B19/W$1 -> 0.82352941 | X19: =$B19/X$1 -> 0.77777778 | Y19: =$B19/Y$1 -> 0.73684211 | Z19: =$B19/Z$1 -> 0.7 | AA19: =$B19/AA$1 -> 0.63636364 | ... AJ19: =$B19/AJ$1 -> 0.35
B20: 0.75 | U20: =$B20/U$1 -> 1 | V20: =$B20/V$1 -> 0.9375 | W20: =$B20/W$1 -> 0.88235294 | X20: =$B20/X$1 -> 0.83333333 | Y20: =$B20/Y$1 -> 0.78947368 | Z20: =$B20/Z$1 -> 0.75 | AA20: =$B20/AA$1 -> 0.68181818 | AB20: =$B20/AB$1 -> 0.625 | ... AJ20: =$B20/AJ$1 -> 0.375
B21: 0.8 | V21: =$B21/V$1 -> 1 | W21: =$B21/W$1 -> 0.94117647 | X21: =$B21/X$1 -> 0.88888889 | Y21: =$B21/Y$1 -> 0.84210526 | Z21: =$B21/Z$1 -> 0.8 | AA21: =$B21/AA$1 -> 0.72727273 | AB21: =$B21/AB$1 -> 0.66666667 | AC21: =$B21/AC$1 -> 0.61538462 | ... AJ21: =$B21/AJ$1 -> 0.4
B22: 0.85 | W22: =$B22/W$1 -> 1 | X22: =$B22/X$1 -> 0.94444444 | Y22: =$B22/Y$1 -> 0.89473684 | Z22: =$B22/Z$1 -> 0.85 | AA22: =$B22/AA$1 -> 0.77272727 | AB22: =$B22/AB$1 -> 0.70833333 | AC22: =$B22/AC$1 -> 0.65384615 | AD22: =$B22/AD$1 -> 0.60714286 | ... AJ22: =$B22/AJ$1 -> 0.425
B23: 0.9 | X23: =$B23/X$1 -> 1 | Y23: =$B23/Y$1 -> 0.94736842 | Z23: =$B23/Z$1 -> 0.9 | AA23: =$B23/AA$1 -> 0.81818182 | AB23: =$B23/AB$1 -> 0.75 | AC23: =$B23/AC$1 -> 0.69230769 | AD23: =$B23/AD$1 -> 0.64285714 | AE23: =$B23/AE$1 -> 0.6 | ... AJ23: =$B23/AJ$1 -> 0.45
B24: 0.95 | Y24: =$B24/Y$1 -> 1 | Z24: =$B24/Z$1 -> 0.95 | AA24: =$B24/AA$1 -> 0.86363636 | AB24: =$B24/AB$1 -> 0.79166667 | AC24: =$B24/AC$1 -> 0.73076923 | AD24: =$B24/AD$1 -> 0.67857143 | AE24: =$B24/AE$1 -> 0.63333333 | AF24: =$B24/AF$1 -> 0.59375 | ... AJ24: =$B24/AJ$1 -> 0.475
B25: 1 | Z25: =$B25/Z$1 -> 1 | AA25: =$B25/AA$1 -> 0.90909091 | AB25: =$B25/AB$1 -> 0.83333333 | AC25: =$B25/AC$1 -> 0.76923077 | AD25: =$B25/AD$1 -> 0.71428571 | AE25: =$B25/AE$1 -> 0.66666667 | AF25: =$B25/AF$1 -> 0.625 | AG25: =$B25/AG$1 -> 0.58823529 | ... AJ25: =$B25/AJ$1 -> 0.5
B26: 1.1 | AA26: =$B26/AA$1 -> 1 | AB26: =$B26/AB$1 -> 0.91666667 | AC26: =$B26/AC$1 -> 0.84615385 | AD26: =$B26/AD$1 -> 0.78571429 | AE26: =$B26/AE$1 -> 0.73333333 | AF26: =$B26/AF$1 -> 0.6875 | AG26: =$B26/AG$1 -> 0.64705882 | AH26: =$B26/AH$1 -> 0.61111111 | ... AJ26: =$B26/AJ$1 -> 0.55
B27: 1.2 | AB27: =$B27/AB$1 -> 1 | AC27: =$B27/AC$1 -> 0.92307692 | AD27: =$B27/AD$1 -> 0.85714286 | AE27: =$B27/AE$1 -> 0.8 | AF27: =$B27/AF$1 -> 0.75 | AG27: =$B27/AG$1 -> 0.70588235 | AH27: =$B27/AH$1 -> 0.66666667 | AI27: =$B27/AI$1 -> 0.63157895 | AJ27: =$B27/AJ$1 -> 0.6
B28: 1.3 | AC28: =$B28/AC$1 -> 1 | AD28: =$B28/AD$1 -> 0.92857143 | AE28: =$B28/AE$1 -> 0.86666667 | AF28: =$B28/AF$1 -> 0.8125 | AG28: =$B28/AG$1 -> 0.76470588 | AH28: =$B28/AH$1 -> 0.72222222 | AI28: =$B28/AI$1 -> 0.68421053 | AJ28: =$B28/AJ$1 -> 0.65
B29: 1.4 | AD29: =$B29/AD$1 -> 1 | AE29: =$B29/AE$1 -> 0.93333333 | AF29: =$B29/AF$1 -> 0.875 | AG29: =$B29/AG$1 -> 0.82352941 | AH29: =$B29/AH$1 -> 0.77777778 | AI29: =$B29/AI$1 -> 0.73684211 | AJ29: =$B29/AJ$1 -> 0.7
B30: 1.5 | AE30: =$B30/AE$1 -> 1 | AF30: =$B30/AF$1 -> 0.9375 | AG30: =$B30/AG$1 -> 0.88235294 | AH30: =$B30/AH$1 -> 0.83333333 | AI30: =$B30/AI$1 -> 0.78947368 | AJ30: =$B30/AJ$1 -> 0.75
B31: 1.6 | AF31: =$B31/AF$1 -> 1 | AG31: =$B31/AG$1 -> 0.94117647 | AH31: =$B31/AH$1 -> 0.88888889 | AI31: =$B31/AI$1 -> 0.84210526 | AJ31: =$B31/AJ$1 -> 0.8
B32: 1.7 | AG32: =$B32/AG$1 -> 1 | AH32: =$B32/AH$1 -> 0.94444444 | AI32: =$B32/AI$1 -> 0.89473684 | AJ32: =$B32/AJ$1 -> 0.85
B33: 1.8 | AH33: =$B33/AH$1 -> 1 | AI33: =$B33/AI$1 -> 0.94736842 | AJ33: =$B33/AJ$1 -> 0.9
B34: 1.9 | AI34: =$B34/AI$1 -> 1 | AJ34: =$B34/AJ$1 -> 0.95
B35: 2 | AJ35: =$B35/AJ$1 -> 1

Sheet БОВ (1)
B2: БОВ-1 | I2: Диаметр трубопровода | W2: Клапан | AJ2: Насос | AN2: TOP-SD | AO2: Yonos MAXO-D | AP2: Stratos-D | AS2: Теплообменник | BN2: Х1 | BR2: Х2 | BV2: Х3 | CA2: Х4 | CE2: Х5 | CI2: Х6 | CR2: Х7 | CW2: Х8 | DA2: Х9 | DE2: Х10 | DI2: Х11
J3: D1 | K3: l | L3: h | O3: D2 | P3: l | Q3: h | S3: Dп | T3: l | U3: h | W3: IMI Hydronic | X3: Siemens | Y3: Danfoss | Z3: IMI Hydronic | AC3: Siemens | AF3: Danfoss | AJ3: Gнас | AS3: 150-75 | AX3: 130-75 | BC3: 115-75 | BH3: 105-75 | BN3: № | BO3: Схема | BR3: № | BS3: Ду | BV3: № | BW3: Ду | BX3: Kv | CA3: № | CB3: Производитель | CE3: № | CF3: Ду | CI3: № | CJ3: Тип насоса | CM3: Тип насоса | CP3: Тип насоса | CS3: № | CT3: Тип насоса | CX3: № | CY3: Тип ТО | DB3: № | DC3: Контролл. | DF3: № | DG3: Контролл. | DJ3: № | DK3: ША
A4: Q | B4: ='ОЛ(4)'!C14 -> 0.2 | C4: Гкал/ч | E4: G1 | F4: =B4*1000/(B5-B6) -> 3.3333333 | I4: =IF($B$12<12,(IF((L4>4)*AND(L4<16),2,0)),IF((L4>4)*AND(L4<20),2,0)) -> 0 | J4: 15 | K4: =1/POWER(1.14+2*LOG10((J4/1000)/($K$21/1000)),2) -> 0.059655827 | L4: =0.00638*K4*POWER($F$4,2)/(POWER(J4/1000,5)*$K$20) -> 5810.6932 | N4: =IF((Q4>4)*AND(Q4<20),1,0) -> 0 | O4: 15 | P4: =1/POWER(1.14+2*LOG10((O4/1000)/($K$21/1000)),2) -> 0.059655827 | Q4: =0.00638*P4*POWER($F$11,2)/(POWER(O4/1000,5)*$K$20) -> 33469.593 | R4: =IF((U4>4)*AND(U4<20),1,0) -> 0 | S4: 15 | T4: =1/POWER(1.14+2*LOG10((S4/1000)/($K$21/1000)),2) -> 0.059655827 | U4: =0.00638*T4*POWER($F$16,2)/(POWER(S4/1000,5)*$K$20) -> 79.542579 | W4: ΔPкл | X4: =IF(B12=0,0,IF(B12>12,3,1.8)) -> 3 | Z4: =IF(AB4>$X$5,1,0) -> 0 | AA4: 15 | AB4: 1.6 | AC4: =IF(AE4>$X$5,1,0) -> 0 | AD4: 15 | AE4: 1.6 | AF4: =IF(AH4>$X$5,1,0) -> 0 | AG4: 15 | AH4: 1.6 | AJ4: 4 | AK4: =IF($F$13<AJ4,1,0) -> 0 | AL4: TOP-SD 32/10 3~ | AM4: =IF($F$13<AJ4,1,0) -> 0 | AN4: Yonos MAXO-D 32/0,5-11 | AO4: =IF($F$13<AJ4,1,0) -> 0 | AP4: Stratos-D 32/1-12 | AS4: 0.1 | AT4: =IF($B$4<AS4,1,0) -> 0 | AU4: НН08 | AV4: =IF($B$4<AS4,1,0) -> 0 | AW4: 1 | AX4: 0.1 | AY4: =IF($B$4<AX4,1,0) -> 0 | AZ4: НН08 | BA4: =IF($B$4<AX4,1,0) -> 0 | BB4: 1 | BC4: 0.14 | BD4: =IF($B$4<BC4,1,0) -> 0 | BE4: НН08 | BF4: =IF($B$4<BC4,1,0) -> 0 | BG4: 1 | BH4: 0.05 | BI4: =IF($B$4<BH4,1,0) -> 0 | BJ4: НН08 | BK4: =IF($B$4<BH4,1,0) -> 0 | BL4: 1 | BN4: 1 | BO4: Зависимая | BQ4: =IF($F$5=BS4,1,0) -> 0 | BR4: 01 | BS4: 15 | BU4: =IF($F$7=BX4,1,0) -> 0 | BV4: 01 | BW4: 15 | BX4: 0.63 | BZ4: =IF($B$14=CB4,1,0) -> 0 | CA4: 1 | CB4: IMI Hydronic | CD4: =IF($F$12=CF4,1,0) -> 0 | CE4: 01 | CF4: 15 | CH4: =IF($E$14=CJ4,1,0) -> 0 | CI4: 1 | CJ4: TOP-SD 32/10 3~ | CK4: =IF($E$14=CM4,1,0) -> 0 | CL4: 1 | CM4: Yonos MAXO-D 32/0,5-11 | CN4: =IF($E$14=CP4,1,0) -> 0 | CO4: 1 | CP4: Stratos-D 32/1-12 | CR4: =IF(OR(E14="DPL 80/115-2,2/2",E14="DPL 100/175-3/4"),1,0) -> 0 | CS4: 5 | CW4: =IF($E$9=CY4,1,0) -> 1 | CX4: 0 | CY4: отсутствует | DA4: =IF($F$9=DC4,1,0) -> 1 | DB4: 0 | DC4: отсутствует | DE4: =IF($B$16=DG4,1,0) -> 1 | DF4: 1 | DG4: Segnetics | DI4: =IF($B$17=DK4,1,0) -> 1 | DJ4: 1 | DK4: отдельный
A5: Т1 | B5: ='ОЛ(4)'!N13 -> 130 | C5: °С | E5: D1 | F5: =VLOOKUP(2,I4:L17,2,0) -> 50 | I5: =IF($B$12<12,(IF((L5>4)*AND(L5<16),2,0)),IF((L5>4)*AND(L5<20),2,0)) -> 0 | J5: 20 | K5: =1/POWER(1.14+2*LOG10((J5/1000)/($K$21/1000)),2) -> 0.0529903 | L5: =0.00638*K5*POWER($F$4,2)/(POWER(J5/1000,5)*$K$20) -> 1224.8355 | N5: =IF((Q5>4)*AND(Q5<20),1,0) -> 0 | O5: 20 | P5: =1/POWER(1.14+2*LOG10((O5/1000)/($K$21/1000)),2) -> 0.0529903 | Q5: =0.00638*P5*POWER($F$11,2)/(POWER(O5/1000,5)*$K$20) -> 7055.0524 | R5: =IF((U5>4)*AND(U5<20),1,0) -> 1 | S5: 20 | T5: =1/POWER(1.14+2*LOG10((S5/1000)/($K$21/1000)),2) -> 0.0529903 | U5: =0.00638*T5*POWER($F$16,2)/(POWER(S5/1000,5)*$K$20) -> 16.766773 | W5: Kvрасч | X5: =F4/SQRT(0.1*X4) -> 6.0858062 | Z5: =IF(AB5>$X$5,1,0) -> 0 | AA5: 15 | AB5: 2.5 | AC5: =IF(AE5>$X$5,1,0) -> 0 | AD5: 15 | AE5: 2.5 | AF5: =IF(AH5>$X$5,1,0) -> 0 | AG5: 15 | AH5: 2.5 | AJ5: 6 | AK5: =IF($F$13<AJ5,1,0) -> 0 | AL5: TOP-SD 40/10 3~ | AM5: =IF($F$13<AJ5,1,0) -> 0 | AN5: Yonos MAXO-D 40/0,5-12 | AO5: =IF($F$13<AJ5,1,0) -> 0 | AP5: Stratos-D 40/1-12 | AS5: 0.25 | AT5: =IF($B$4<AS5,1,0) -> 1 | AU5: НН14 | AV5: =IF($B$4<AS5,1,0) -> 1 | AW5: 1 | AX5: 0.25 | AY5: =IF($B$4<AX5,1,0) -> 1 | AZ5: НН14 | BA5: =IF($B$4<AX5,1,0) -> 1 | BB5: 1 | BC5: 0.45 | BD5: =IF($B$4<BC5,1,0) -> 1 | BE5: НН19 | BF5: =IF($B$4<BC5,1,0) -> 1 | BG5: 1 | BH5: 0.09 | BI5: =IF($B$4<BH5,1,0) -> 0 | BJ5: НН20 | BK5: =IF($B$4<BH5,1,0) -> 0 | BL5: 1 | BN5: 2 | BO5: Независимая | BQ5: =IF($F$5=BS5,1,0) -> 0 | BR5: 02 | BS5: 20 | BU5: =IF($F$7=BX5,1,0) -> 0 | BV5: 02 | BW5: 15 | BX5: 1.25 | BZ5: =IF($B$14=CB5,1,0) -> 0 | CA5: 2 | CB5: Danfoss | CD5: =IF($F$12=CF5,1,0) -> 0 | CE5: 02 | CF5: 20 | CH5: =IF($E$14=CJ5,1,0) -> 0 | CI5: 2 | CJ5: TOP-SD 40/10 3~ | CK5: =IF($E$14=CM5,1,0) -> 0 | CL5: 2 | CM5: Yonos MAXO-D 40/0,5-12 | CN5: =IF($E$14=CP5,1,0) -> 0 | CO5: 2 | CP5: Stratos-D 40/1-12 | CR5: =IF($B$15=CT5,1,0) -> 0 | CS5: 1 | CT5: TOP-SD | CW5: =IF($E$9=CY5,1,0) -> 0 | CX5: 1 | CY5: НН08 | DA5: =IF($F$9=DC5,1,0) -> 0 | DB5: 1 | DC5: 1 | DE5: =IF($B$16=DG5,1,0) -> 0 | DF5: 2 | DG5: Danfoss | DI5: =IF($B$17=DK5,1,0) -> 0 | DJ5: 0 | DK5: Учтен в БОВ-1
A6: Т2 | B6: =IF(OR('ОЛ(4)'!C24="зависимая",'ОЛ(4)'!C24=0),'ОЛ(4)'!R13,IF(('ОЛ(4)'!R13-B8)<5,B8+5,'ОЛ(4)'!R13)) -> 70 | C6: °С | E6: dкл | F6: =VLOOKUP(1,IF(B14="IMI Hydronic",Z4:AB21,IF(B14="Siemens",AC4:AE22,AF4:AH16)),2,0) -> 20 | I6: =IF($B$12<12,(IF((L6>4)*AND(L6<16),2,0)),IF((L6>4)*AND(L6<20),2,0)) -> 0 | J6: 25 | K6: =1/POWER(1.14+2*LOG10((J6/1000)/($K$21/1000)),2) -> 0.048560427 | L6: =0.00638*K6*POWER($F$4,2)/(POWER(J6/1000,5)*$K$20) -> 367.80177 | N6: =IF((Q6>4)*AND(Q6<20),1,0) -> 0 | O6: 25 | P6: =1/POWER(1.14+2*LOG10((O6/1000)/($K$21/1000)),2) -> 0.048560427 | Q6: =0.00638*P6*POWER($F$11,2)/(POWER(O6/1000,5)*$K$20) -> 2118.5382 | R6: =IF((U6>4)*AND(U6<20),1,0) -> 1 | S6: 25 | T6: =1/POWER(1.14+2*LOG10((S6/1000)/($K$21/1000)),2) -> 0.048560427 | U6: =0.00638*T6*POWER($F$16,2)/(POWER(S6/1000,5)*$K$20) -> 5.0348385 | Z6: =IF(AB6>$X$5,1,0) -> 0 | AA6: 15 | AB6: 4 | AC6: =IF(AE6>$X$5,1,0) -> 0 | AD6: 15 | AE6: 4 | AF6: =IF(AH6>$X$5,1,0) -> 0 | AG6: 15 | AH6: 4 | AJ6: 10 | AK6: =IF($F$13<AJ6,1,0) -> 1 | AL6: TOP-SD 50/10 3~ | AM6: =IF($F$13<AJ6,1,0) -> 1 | AN6: Yonos MAXO-D 50/0,5-12 | AO6: =IF($F$13<AJ6,1,0) -> 1 | AP6: Stratos-D 50/1-12 | AS6: 0.67 | AT6: =IF($B$4<AS6,1,0) -> 1 | AU6: НН19 | AV6: =IF($B$4<AS6,1,0) -> 1 | AW6: 1 | AX6: 0.575 | AY6: =IF($B$4<AX6,1,0) -> 1 | AZ6: НН19 | BA6: =IF($B$4<AX6,1,0) -> 1 | BB6: 1 | BC6: 0.71 | BD6: =IF($B$4<BC6,1,0) -> 1 | BE6: НН19 | BF6: =IF($B$4<BC6,1,0) -> 1 | BG6: 2 | BH6: 0.3 | BI6: =IF($B$4<BH6,1,0) -> 1 | BJ6: НН19 | BK6: =IF($B$4<BH6,1,0) -> 1 | BL6: 1 | BQ6: =IF($F$5=BS6,1,0) -> 0 | BR6: 03 | BS6: 25 | BU6: =IF($F$7=BX6,1,0) -> 0 | BV6: 03 | BW6: 15 | BX6: 1.6 | BZ6: =IF($B$14=CB6,1,0) -> 1 | CA6: 3 | CB6: Siemens | CD6: =IF($F$12=CF6,1,0) -> 0 | CE6: 03 | CF6: 25 | CH6: =IF($E$14=CJ6,1,0) -> 0 | CI6: 3 | CJ6: TOP-SD 50/10 3~ | CK6: =IF($E$14=CM6,1,0) -> 1 | CL6: 3 | CM6: Yonos MAXO-D 50/0,5-12 | CN6: =IF($E$14=CP6,1,0) -> 0 | CO6: 3 | CP6: Stratos-D 50/1-12 | CR6: =IF($B$15=CT6,1,0) -> 1 | CS6: 2 | CT6: Yonos MAXO-D | CW6: =IF($E$9=CY6,1,0) -> 0 | CX6: 2 | CY6: НН14 | DA6: =IF($F$9=DC6,1,0) -> 0 | DB6: 2 | DC6: 2 | DE6: =IF($B$16=DG6,1,0) -> 0 | DF6: 3 | DG6: Siemens
A7: Т11 | B7: ='ОЛ(4)'!N14 -> 95 | C7: °С | E7: Kv | F7: =VLOOKUP(1,IF(B14="IMI Hydronic",Z4:AB21,IF(B14="Siemens",AC4:AE22,AF4:AH16)),3,0) -> 6.3 | I7: =IF($B$12<12,(IF((L7>4)*AND(L7<16),2,0)),IF((L7>4)*AND(L7<20),2,0)) -> 0 | J7: 32 | K7: =1/POWER(1.14+2*LOG10((J7/1000)/($K$21/1000)),2) -> 0.044277322 | L7: =0.00638*K7*POWER($F$4,2)/(POWER(J7/1000,5)*$K$20) -> 97.602922 | N7: =IF((Q7>4)*AND(Q7<20),1,0) -> 0 | O7: 32 | P7: =1/POWER(1.14+2*LOG10((O7/1000)/($K$21/1000)),2) -> 0.044277322 | Q7: =0.00638*P7*POWER($F$11,2)/(POWER(O7/1000,5)*$K$20) -> 562.19283 | R7: =IF((U7>4)*AND(U7<20),1,0) -> 0 | S7: 32 | T7: =1/POWER(1.14+2*LOG10((S7/1000)/($K$21/1000)),2) -> 0.044277322 | U7: =0.00638*T7*POWER($F$16,2)/(POWER(S7/1000,5)*$K$20) -> 1.3360864 | Z7: =IF(AB7>$X$5,1,0) -> 1 | AA7: 20 | AB7: 6.3 | AC7: =IF(AE7>$X$5,1,0) -> 1 | AD7: 20 | AE7: 6.3 | AF7: =IF(AH7>$X$5,1,0) -> 1 | AG7: 20 | AH7: 6.3 | AJ7: 14 | AK7: =IF($F$13<AJ7,1,0) -> 1 | AL7: TOP-SD 40/15 3~ | AM7: =IF($F$13<AJ7,1,0) -> 1 | AN7: Yonos MAXO-D 40/0,5-16 | AO7: =IF($F$13<AJ7,1,0) -> 1 | AP7: Stratos-D 40/1-16 | AS7: 1 | AT7: =IF($B$4<AS7,1,0) -> 1 | AU7: НН19 | AV7: =IF($B$4<AS7,1,0) -> 1 | AW7: 2 | AX7: 0.9 | AY7: =IF($B$4<AX7,1,0) -> 1 | AZ7: НН19 | BA7: =IF($B$4<AX7,1,0) -> 1 | BB7: 2 | BC7: 0.95 | BD7: =IF($B$4<BC7,1,0) -> 1 | BE7: НН19 | BF7: =IF($B$4<BC7,1,0) -> 1 | BG7: 3 | BH7: 0.48 | BI7: =IF($B$4<BH7,1,0) -> 1 | BJ7: НН19 | BK7: =IF($B$4<BH7,1,0) -> 1 | BL7: 2 | BQ7: =IF($F$5=BS7,1,0) -> 0 | BR7: 04 | BS7: 32 | BU7: =IF($F$7=BX7,1,0) -> 0 | BV7: 04 | BW7: 15 | BX7: 2.5 | CD7: =IF($F$12=CF7,1,0) -> 0 | CE7: 04 | CF7: 32 | CH7: =IF($E$14=CJ7,1,0) -> 0 | CI7: 4 | CJ7: TOP-SD 40/15 3~ | CK7: =IF($E$14=CM7,1,0) -> 0 | CL7: 4 | CM7: Yonos MAXO-D 40/0,5-16 | CN7: =IF($E$14=CP7,1,0) -> 0 | CO7: 4 | CP7: Stratos-D 40/1-16 | CR7: =IF($B$15=CT7,1,0) -> 0 | CS7: 3 | CT7: Stratos-D | CW7: =IF($E$9=CY7,1,0) -> 0 | CX7: 3 | CY7: НН20 | DA7: =IF($F$9=DC7,1,0) -> 0 | DB7: 3 | DC7: 3
A8: Т21 | B8: ='ОЛ(4)'!R14 -> 70 | C8: °С | E8: ΔPкл | F8: =(F4^2/F7^2)*10 -> 2.7994737 | I8: =IF($B$12<12,(IF((L8>4)*AND(L8<16),2,0)),IF((L8>4)*AND(L8<20),2,0)) -> 0 | J8: 40 | K8: =1/POWER(1.14+2*LOG10((J8/1000)/($K$21/1000)),2) -> 0.040875226 | L8: =0.00638*K8*POWER($F$4,2)/(POWER(J8/1000,5)*$K$20) -> 29.525114 | N8: =IF((Q8>4)*AND(Q8<20),1,0) -> 0 | O8: 40 | P8: =1/POWER(1.14+2*LOG10((O8/1000)/($K$21/1000)),2) -> 0.040875226 | Q8: =0.00638*P8*POWER($F$11,2)/(POWER(O8/1000,5)*$K$20) -> 170.06465 | R8: =IF((U8>4)*AND(U8<20),1,0) -> 0 | S8: 40 | T8: =1/POWER(1.14+2*LOG10((S8/1000)/($K$21/1000)),2) -> 0.040875226 | U8: =0.00638*T8*POWER($F$16,2)/(POWER(S8/1000,5)*$K$20) -> 0.40416928 | Z8: =IF(AB8>$X$5,1,0) -> 1 | AA8: 25 | AB8: 10 | AC8: =IF(AE8>$X$5,1,0) -> 1 | AD8: 25 | AE8: 10 | AF8: =IF(AH8>$X$5,1,0) -> 1 | AG8: 25 | AH8: 10 | AJ8: 25 | AK8: =IF($F$13<AJ8,1,0) -> 1 | AL8: TOP-SD 50/15 3~ | AM8: =IF($F$13<AJ8,1,0) -> 1 | AN8: Yonos MAXO-D 50/0,5-16 | AO8: =IF($F$13<AJ8,1,0) -> 1 | AP8: Stratos-D 50/1-16 | AS8: 1.25 | AT8: =IF($B$4<AS8,1,0) -> 1 | AU8: НН19 | AV8: =IF($B$4<AS8,1,0) -> 1 | AW8: 3 | AX8: 1.16 | AY8: =IF($B$4<AX8,1,0) -> 1 | AZ8: НН19 | BA8: =IF($B$4<AX8,1,0) -> 1 | BB8: 3 | BC8: 1.25 | BD8: =IF($B$4<BC8,1,0) -> 1 | BE8: НН19 | BF8: =IF($B$4<BC8,1,0) -> 1 | BG8: 4 | BH8: 0.66 | BI8: =IF($B$4<BH8,1,0) -> 1 | BJ8: НН19 | BK8: =IF($B$4<BH8,1,0) -> 1 | BL8: 3 | BQ8: =IF($F$5=BS8,1,0) -> 0 | BR8: 05 | BS8: 40 | BU8: =IF($F$7=BX8,1,0) -> 0 | BV8: 05 | BW8: 15 | BX8: 4 | CD8: =IF($F$12=CF8,1,0) -> 0 | CE8: 05 | CF8: 40 | CH8: =IF($E$14=CJ8,1,0) -> 0 | CI8: 5 | CJ8: TOP-SD 50/15 3~ | CK8: =IF($E$14=CM8,1,0) -> 0 | CL8: 5 | CM8: Yonos MAXO-D 50/0,5-16 | CN8: =IF($E$14=CP8,1,0) -> 0 | CO8: 5 | CP8: Stratos-D 50/1-16 | CW8: =IF($E$9=CY8,1,0) -> 0 | CX8: 4 | CY8: НН19 | DA8: =IF($F$9=DC8,1,0) -> 0 | DB8: 4 | DC8: 4
A9: Р1 | B9: ='ОЛ(4)'!W13*100 -> 60 | C9: м.в.ст. | E9: =IF('ОЛ(4)'!C24="ЗАВИСИМАЯ","ОТСУТСТВУЕТ",VLOOKUP(1,IF(B5=150,AT4:AU11,IF(B5=130,AY4:AZ11,IF(B5=115,BD4:BE10,IF(B5=105,BI4:BJ13,0)))),2,0)) -> ОТСУТСТВУЕТ | F9: =IF('ОЛ(4)'!C24="ЗАВИСИМАЯ","ОТСУТСТВУЕТ",VLOOKUP(1,IF(B5=150,AV4:AW11,IF(B5=130,BA4:BB11,IF(B5=115,BF4:BG10,IF(B5=105,BK4:BL13,0)))),2,0)) -> ОТСУТСТВУЕТ | I9: =IF($B$12<12,(IF((L9>4)*AND(L9<16),2,0)),IF((L9>4)*AND(L9<20),2,0)) -> 2 | J9: 50 | K9: =1/POWER(1.14+2*LOG10((J9/1000)/($K$21/1000)),2) -> 0.037850687 | L9: =0.00638*K9*POWER($F$4,2)/(POWER(J9/1000,5)*$K$20) -> 8.9589086 | N9: =IF((Q9>4)*AND(Q9<20),1,0) -> 0 | O9: 50 | P9: =1/POWER(1.14+2*LOG10((O9/1000)/($K$21/1000)),2) -> 0.037850687 | Q9: =0.00638*P9*POWER($F$11,2)/(POWER(O9/1000,5)*$K$20) -> 51.603313 | R9: =IF((U9>4)*AND(U9<20),1,0) -> 0 | S9: 50 | T9: =1/POWER(1.14+2*LOG10((S9/1000)/($K$21/1000)),2) -> 0.037850687 | U9: =0.00638*T9*POWER($F$16,2)/(POWER(S9/1000,5)*$K$20) -> 0.1226385 | Z9: =IF(AB9>$X$5,1,0) -> 1 | AA9: 32 | AB9: 16 | AC9: =IF(AE9>$X$5,1,0) -> 1 | AD9: 32 | AE9: 16 | AF9: =IF(AH9>$X$5,1,0) -> 1 | AG9: 32 | AH9: 16 | AJ9: 30 | AK9: =IF($F$13<AJ9,1,0) -> 1 | AL9: TOP-SD 65/15 3~ | AM9: =IF($F$13<AJ9,1,0) -> 1 | AN9: Yonos MAXO-D 65/0,5-16 | AO9: =IF($F$13<AJ9,1,0) -> 1 | AP9: Stratos-D 65/1-12 | AS9: 1.3 | AT9: =IF($B$4<AS9,1,0) -> 1 | AU9: НН19 | AV9: =IF($B$4<AS9,1,0) -> 1 | AW9: 4 | AX9: 1.3 | AY9: =IF($B$4<AX9,1,0) -> 1 | AZ9: НН19 | BA9: =IF($B$4<AX9,1,0) -> 1 | BB9: 4 | BC9: 1.8 | BD9: =IF($B$4<BC9,1,0) -> 1 | BE9: НН47 | BF9: =IF($B$4<BC9,1,0) -> 1 | BG9: 2 | BH9: 0.91 | BI9: =IF($B$4<BH9,1,0) -> 1 | BJ9: НН19 | BK9: =IF($B$4<BH9,1,0) -> 1 | BL9: 4 | BQ9: =IF($F$5=BS9,1,0) -> 1 | BR9: 06 | BS9: 50 | BU9: =IF($F$7=BX9,1,0) -> 0 | BV9: 06 | BW9: 20 | BX9: 5 | CD9: =IF($F$12=CF9,1,0) -> 0 | CE9: 06 | CF9: 50 | CH9: =IF($E$14=CJ9,1,0) -> 0 | CI9: 6 | CJ9: TOP-SD 65/15 3~ | CK9: =IF($E$14=CM9,1,0) -> 0 | CL9: 6 | CM9: Yonos MAXO-D 65/0,5-16 | CN9: =IF($E$14=CP9,1,0) -> 0 | CO9: 6 | CP9: Stratos-D 65/1-12 | CW9: =IF($E$9=CY9,1,0) -> 0 | CX9: 5 | CY9: НН47 | DA9: =IF($F$9=DC9,1,0) -> 0 | DB9: 5 | DC9: 5
A10: Р2 | B10: ='ОЛ(4)'!AC13*100 -> 40 | C10: м.в.ст. | I10: =IF($B$12<12,(IF((L10>4)*AND(L10<16),2,0)),IF((L10>4)*AND(L10<20),2,0)) -> 0 | J10: 65 | K10: =1/POWER(1.14+2*LOG10((J10/1000)/($K$21/1000)),2) -> 0.034705101 | L10: =0.00638*K10*POWER($F$4,2)/(POWER(J10/1000,5)*$K$20) -> 2.2123707 | N10: =IF((Q10>4)*AND(Q10<20),1,0) -> 1 | O10: 65 | P10: =1/POWER(1.14+2*LOG10((O10/1000)/($K$21/1000)),2) -> 0.034705101 | Q10: =0.00638*P10*POWER($F$11,2)/(POWER(O10/1000,5)*$K$20) -> 12.743255 | R10: =IF((U10>4)*AND(U10<20),1,0) -> 0 | S10: 65 | T10: =1/POWER(1.14+2*LOG10((S10/1000)/($K$21/1000)),2) -> 0.034705101 | U10: =0.00638*T10*POWER($F$16,2)/(POWER(S10/1000,5)*$K$20) -> 0.030285143 | Z10: =IF(AB10>$X$5,1,0) -> 1 | AA10: 40 | AB10: 20 | AC10: =IF(AE10>$X$5,1,0) -> 1 | AD10: 40 | AE10: 25 | AF10: =IF(AH10>$X$5,1,0) -> 1 | AG10: 40 | AH10: 25 | AJ10: 40 | AK10: =IF($F$13<AJ10,1,0) -> 1 | AL10: TOP-SD 80/15 3~ | AM10: =IF($F$13<AJ10,1,0) -> 1 | AN10: Yonos MAXO-D 80/0,5-12 | AO10: =IF($F$13<AJ10,1,0) -> 1 | AP10: Stratos-D 80/1-12 | AS10: 1.65 | AT10: =IF($B$4<AS10,1,0) -> 1 | AU10: НН47 | AV10: =IF($B$4<AS10,1,0) -> 1 | AW10: 1 | AX10: 1.4 | AY10: =IF($B$4<AX10,1,0) -> 1 | AZ10: НН47 | BA10: =IF($B$4<AX10,1,0) -> 1 | BB10: 1 | BC10: 2.001 | BD10: =IF($B$4<BC10,1,0) -> 1 | BE10: НН62 | BF10: =IF($B$4<BC10,1,0) -> 1 | BG10: 1 | BH10: 1.1 | BI10: =IF($B$4<BH10,1,0) -> 1 | BJ10: НН19 | BK10: =IF($B$4<BH10,1,0) -> 1 | BL10: 5 | BQ10: =IF($F$5=BS10,1,0) -> 0 | BR10: 07 | BS10: 65 | BU10: =IF($F$7=BX10,1,0) -> 1 | BV10: 07 | BW10: 20 | BX10: 6.3 | CD10: =IF($F$12=CF10,1,0) -> 1 | CE10: 07 | CF10: 65 | CH10: =IF($E$14=CJ10,1,0) -> 0 | CI10: 7 | CJ10: TOP-SD 80/15 3~ | CK10: =IF($E$14=CM10,1,0) -> 0 | CL10: 7 | CM10: Yonos MAXO-D 80/0,5-12 | CN10: =IF($E$14=CP10,1,0) -> 0 | CO10: 7 | CP10: Stratos-D 80/1-12 | CW10: =IF($E$9=CY10,1,0) -> 0 | CX10: 6 | CY10: НН62
A11: Δpсов | B11: ='ОЛ(4)'!Z14 -> 0 | C11: м.в.ст. | E11: G2 | F11: =B4*1000/(B7-B8) -> 8 | I11: =IF($B$12<12,(IF((L11>4)*AND(L11<16),2,0)),IF((L11>4)*AND(L11<20),2,0)) -> 0 | J11: 80 | K11: =1/POWER(1.14+2*LOG10((J11/1000)/($K$21/1000)),2) -> 0.032485498 | L11: =0.00638*K11*POWER($F$4,2)/(POWER(J11/1000,5)*$K$20) -> 0.73328189 | N11: =IF((Q11>4)*AND(Q11<20),1,0) -> 1 | O11: 80 | P11: =1/POWER(1.14+2*LOG10((O11/1000)/($K$21/1000)),2) -> 0.032485498 | Q11: =0.00638*P11*POWER($F$11,2)/(POWER(O11/1000,5)*$K$20) -> 4.2237037 | R11: =IF((U11>4)*AND(U11<20),1,0) -> 0 | S11: 80 | T11: =1/POWER(1.14+2*LOG10((S11/1000)/($K$21/1000)),2) -> 0.032485498 | U11: =0.00638*T11*POWER($F$16,2)/(POWER(S11/1000,5)*$K$20) -> 0.010037896 | Z11: =IF(AB11>$X$5,1,0) -> 1 | AA11: 40 | AB11: 25 | AC11: =IF(AE11>$X$5,1,0) -> 1 | AD11: 50 | AE11: 31.5 | AF11: =IF(AH11>$X$5,1,0) -> 1 | AG11: 50 | AH11: 40 | AJ11: 50 | AK11: =IF($F$13<AJ11,1,0) -> 1 | AL11: TOP-SD 80/20 3~ | AM11: =IF($F$13<AJ11,1,0) -> 1 | AN11: DPL 80/115-2,2/2 | AO11: =IF($F$13<AJ11,1,0) -> 1 | AP11: DPL 80/115-2,2/2 | AS11: 2.001 | AT11: =IF($B$4<AS11,1,0) -> 1 | AU11: НН47 | AV11: =IF($B$4<AS11,1,0) -> 1 | AW11: 2 | AX11: 2.001 | AY11: =IF($B$4<AX11,1,0) -> 1 | AZ11: НН47 | BA11: =IF($B$4<AX11,1,0) -> 1 | BB11: 2 | BH11: 1.3 | BI11: =IF($B$4<BH11,1,0) -> 1 | BJ11: НН47 | BK11: =IF($B$4<BH11,1,0) -> 1 | BL11: 2 | BQ11: =IF($F$5=BS11,1,0) -> 0 | BR11: 08 | BS11: 80 | BU11: =IF($F$7=BX11,1,0) -> 0 | BV11: 08 | BW11: 25 | BX11: 8 | CD11: =IF($F$12=CF11,1,0) -> 0 | CE11: 08 | CF11: 80 | CH11: =IF($E$14=CJ11,1,0) -> 0 | CI11: 8 | CJ11: TOP-SD 80/20 3~
A12: ΔPтс | B12: =B9-B10 -> 20 | C12: м.в.ст. | E12: D2 | F12: =VLOOKUP(1,N4:Q17,2,0) -> 65 | I12: =IF($B$12<12,(IF((L12>4)*AND(L12<16),2,0)),IF((L12>4)*AND(L12<20),2,0)) -> 0 | J12: 100 | K12: =1/POWER(1.14+2*LOG10((J12/1000)/($K$21/1000)),2) -> 0.030329451 | L12: =0.00638*K12*POWER($F$4,2)/(POWER(J12/1000,5)*$K$20) -> 0.22433442 | N12: =IF((Q12>4)*AND(Q12<20),1,0) -> 0 | O12: 100 | P12: =1/POWER(1.14+2*LOG10((O12/1000)/($K$21/1000)),2) -> 0.030329451 | Q12: =0.00638*P12*POWER($F$11,2)/(POWER(O12/1000,5)*$K$20) -> 1.2921663 | R12: =IF((U12>4)*AND(U12<20),1,0) -> 0 | S12: 100 | T12: =1/POWER(1.14+2*LOG10((S12/1000)/($K$21/1000)),2) -> 0.030329451 | U12: =0.00638*T12*POWER($F$16,2)/(POWER(S12/1000,5)*$K$20) -> 0.0030709139 | Z12: =IF(AB12>$X$5,1,0) -> 1 | AA12: 50 | AB12: 31.5 | AC12: =IF(AE12>$X$5,1,0) -> 1 | AD12: 50 | AE12: 40 | AF12: =IF(AH12>$X$5,1,0) -> 1 | AG12: 65 | AH12: 63 | AJ12: 60 | AK12: =IF($F$13<AJ12,1,0) -> 1 | AL12: DPL 80/115-2,2/2 | AM12: =IF($F$13<AJ12,1,0) -> 1 | AN12: DPL 80/115-2,2/2 | AO12: =IF($F$13<AJ12,1,0) -> 1 | AP12: DPL 80/115-2,2/2 | BH12: 1.45 | BI12: =IF($B$4<BH12,1,0) -> 1 | BJ12: НН62 | BK12: =IF($B$4<BH12,1,0) -> 1 | BL12: 1 | BQ12: =IF($F$5=BS12,1,0) -> 0 | BR12: 09 | BS12: 100 | BU12: =IF($F$7=BX12,1,0) -> 0 | BV12: 09 | BW12: 25 | BX12: 10 | CD12: =IF($F$12=CF12,1,0) -> 0 | CE12: 09 | CF12: 100 | CH12: =IF($E$14=CJ12,1,0) -> 0
E13: Gнас | F13: =F11*1.1 -> 8.8 | I13: =IF($B$12<12,(IF((L13>4)*AND(L13<16),2,0)),IF((L13>4)*AND(L13<20),2,0)) -> 0 | J13: 125 | K13: =1/POWER(1.14+2*LOG10((J13/1000)/($K$21/1000)),2) -> 0.028381136 | L13: =0.00638*K13*POWER($F$4,2)/(POWER(J13/1000,5)*$K$20) -> 0.068787745 | N13: =IF((Q13>4)*AND(Q13<20),1,0) -> 0 | O13: 125 | P13: =1/POWER(1.14+2*LOG10((O13/1000)/($K$21/1000)),2) -> 0.028381136 | Q13: =0.00638*P13*POWER($F$11,2)/(POWER(O13/1000,5)*$K$20) -> 0.39621741 | R13: =IF((U13>4)*AND(U13<20),1,0) -> 0 | S13: 125 | T13: =1/POWER(1.14+2*LOG10((S13/1000)/($K$21/1000)),2) -> 0.028381136 | U13: =0.00638*T13*POWER($F$16,2)/(POWER(S13/1000,5)*$K$20) -> 0.00094163544 | Z13: =IF(AB13>$X$5,1,0) -> 1 | AA13: 50 | AB13: 40 | AC13: =IF(AE13>$X$5,1,0) -> 1 | AD13: 65 | AE13: 50 | AF13: =IF(AH13>$X$5,1,0) -> 1 | AG13: 80 | AH13: 100 | AJ13: 90 | AK13: =IF($F$13<AJ13,1,0) -> 1 | AL13: DPL 100/175-3/4 | AM13: =IF($F$13<AJ13,1,0) -> 1 | AN13: DPL 100/175-3/4 | AO13: =IF($F$13<AJ13,1,0) -> 1 | AP13: DPL 100/175-3/4 | BH13: 2.001 | BI13: =IF($B$4<BH13,1,0) -> 1 | BJ13: НН62 | BK13: =IF($B$4<BH13,1,0) -> 1 | BL13: 2 | BQ13: =IF($F$5=BS13,1,0) -> 0 | BR13: 10 | BS13: 125 | BU13: =IF($F$7=BX13,1,0) -> 0 | BV13: 10 | BW13: 32 | BX13: 12.5 | CD13: =IF($F$12=CF13,1,0) -> 0 | CE13: 10 | CF13: 125 | CH13: =IF($E$14=CJ13,1,0) -> 0 | CI13: 10 | CJ13: DPL 80/115-2,2/2 | CK13: =IF($E$14=CM13,1,0) -> 0 | CL13: 10 | CM13: DPL 80/115-2,2/2 | CN13: =IF($E$14=CP13,1,0) -> 0 | CO13: 10 | CP13: DPL 80/115-2,2/2
A14: Клапан | B14: ='ОЛ(4)'!O24 -> Siemens | E14: =VLOOKUP(1,IF(B15="TOP-SD",AK4:AL13,IF(B15="Yonos MAXO-D",AM4:AN13,IF(B15="Stratos-D",AO4:AP13,0))),2,0) -> Yonos MAXO-D 50/0,5-12 | I14: =IF($B$12<12,(IF((L14>4)*AND(L14<16),2,0)),IF((L14>4)*AND(L14<20),2,0)) -> 0 | J14: 150 | K14: =1/POWER(1.14+2*LOG10((J14/1000)/($K$21/1000)),2) -> 0.026925299 | L14: =0.00638*K14*POWER($F$4,2)/(POWER(J14/1000,5)*$K$20) -> 0.026226214 | N14: =IF((Q14>4)*AND(Q14<20),1,0) -> 0 | O14: 150 | P14: =1/POWER(1.14+2*LOG10((O14/1000)/($K$21/1000)),2) -> 0.026925299 | Q14: =0.00638*P14*POWER($F$11,2)/(POWER(O14/1000,5)*$K$20) -> 0.15106299 | R14: =IF((U14>4)*AND(U14<20),1,0) -> 0 | S14: 150 | T14: =1/POWER(1.14+2*LOG10((S14/1000)/($K$21/1000)),2) -> 0.026925299 | U14: =0.00638*T14*POWER($F$16,2)/(POWER(S14/1000,5)*$K$20) -> 0.00035901065 | Z14: =IF(AB14>$X$5,1,0) -> 1 | AA14: 65 | AB14: 50 | AC14: =IF(AE14>$X$5,1,0) -> 1 | AD14: 65 | AE14: 63 | AF14: =IF(AH14>$X$5,1,0) -> 1 | AG14: 100 | AH14: 160 | BQ14: =IF($F$5=BS14,1,0) -> 0 | BR14: 11 | BS14: 150 | BU14: =IF($F$7=BX14,1,0) -> 0 | BV14: 11 | BW14: 32 | BX14: 16 | CD14: =IF($F$12=CF14,1,0) -> 0 | CE14: 11 | CF14: 150 | CH14: =IF($E$14=CJ14,1,0) -> 0 | CI14: 11 | CJ14: DPL 100/175-3/4 | CK14: =IF($E$14=CM14,1,0) -> 0 | CL14: 11 | CM14: DPL 100/175-3/4 | CN14: =IF($E$14=CP14,1,0) -> 0 | CO14: 11 | CP14: DPL 100/175-3/4
A15: Насос | B15: ='ОЛ(4)'!I24 -> Yonos MAXO-D | I15: =IF($B$12<12,(IF((L15>4)*AND(L15<16),2,0)),IF((L15>4)*AND(L15<20),2,0)) -> 0 | J15: 200 | K15: =1/POWER(1.14+2*LOG10((J15/1000)/($K$21/1000)),2) -> 0.024846043 | L15: =0.00638*K15*POWER($F$4,2)/(POWER(J15/1000,5)*$K$20) -> 0.0057429973 | N15: =IF((Q15>4)*AND(Q15<20),1,0) -> 0 | O15: 200 | P15: =1/POWER(1.14+2*LOG10((O15/1000)/($K$21/1000)),2) -> 0.024846043 | Q15: =0.00638*P15*POWER($F$11,2)/(POWER(O15/1000,5)*$K$20) -> 0.033079664 | R15: =IF((U15>4)*AND(U15<20),1,0) -> 0 | S15: 200 | T15: =1/POWER(1.14+2*LOG10((S15/1000)/($K$21/1000)),2) -> 0.024846043 | U15: =0.00638*T15*POWER($F$16,2)/(POWER(S15/1000,5)*$K$20) -> 7.861589e-05 | Z15: =IF(AB15>$X$5,1,0) -> 1 | AA15: 65 | AB15: 63 | AC15: =IF(AE15>$X$5,1,0) -> 1 | AD15: 80 | AE15: 80 | AF15: =IF(AH15>$X$5,1,0) -> 1 | AG15: 125 | AH15: 250 | BQ15: =IF($F$5=BS15,1,0) -> 0 | BR15: 12 | BS15: 200 | BU15: =IF($F$7=BX15,1,0) -> 0 | BV15: 12 | BW15: 40 | BX15: 20 | CD15: =IF($F$12=CF15,1,0) -> 0 | CE15: 12 | CF15: 200
A16: Контр. | B16: ='ОЛ(4)'!U24 -> Segnetics | E16: Gп | F16: =IF(B18="Отопление",11.7,IF(B18="Вентиляция",8.6,30))*B4/6 -> 0.39 | I16: =IF($B$12<12,(IF((L16>4)*AND(L16<16),2,0)),IF((L16>4)*AND(L16<20),2,0)) -> 0 | J16: 250 | K16: =1/POWER(1.14+2*LOG10((J16/1000)/($K$21/1000)),2) -> 0.023394735 | L16: =0.00638*K16*POWER($F$4,2)/(POWER(J16/1000,5)*$K$20) -> 0.0017719418 | N16: =IF((Q16>4)*AND(Q16<20),1,0) -> 0 | O16: 250 | P16: =1/POWER(1.14+2*LOG10((O16/1000)/($K$21/1000)),2) -> 0.023394735 | Q16: =0.00638*P16*POWER($F$11,2)/(POWER(O16/1000,5)*$K$20) -> 0.010206385 | R16: =IF((U16>4)*AND(U16<20),1,0) -> 0 | S16: 250 | T16: =1/POWER(1.14+2*LOG10((S16/1000)/($K$21/1000)),2) -> 0.023394735 | U16: =0.00638*T16*POWER($F$16,2)/(POWER(S16/1000,5)*$K$20) -> 2.4256112e-05 | Z16: =IF(AB16>$X$5,1,0) -> 1 | AA16: 80 | AB16: 80 | AC16: =IF(AE16>$X$5,1,0) -> 1 | AD16: 80 | AE16: 100 | AF16: =IF(AH16>$X$5,1,0) -> 1 | AG16: 150 | AH16: 400 | BU16: =IF($F$7=BX16,1,0) -> 0 | BV16: 13 | BW16: 40 | BX16: 25
A17: ША | B17: ='ОЛ(4)'!AA24 -> Отдельный | E17: Dп | F17: =VLOOKUP(1,R4:U17,2,0) -> 20 | I17: =IF($B$12<12,(IF((L17>4)*AND(L17<16),2,0)),IF((L17>4)*AND(L17<20),2,0)) -> 0 | J17: 300 | K17: =1/POWER(1.14+2*LOG10((J17/1000)/($K$21/1000)),2) -> 0.022301284 | L17: =0.00638*K17*POWER($F$4,2)/(POWER(J17/1000,5)*$K$20) -> 0.00067882052 | N17: =IF((Q17>4)*AND(Q17<20),1,0) -> 0 | O17: 300 | P17: =1/POWER(1.14+2*LOG10((O17/1000)/($K$21/1000)),2) -> 0.022301284 | Q17: =0.00638*P17*POWER($F$11,2)/(POWER(O17/1000,5)*$K$20) -> 0.0039100062 | R17: =IF((U17>4)*AND(U17<20),1,0) -> 0 | S17: 300 | T17: =1/POWER(1.14+2*LOG10((S17/1000)/($K$21/1000)),2) -> 0.022301284 | U17: =0.00638*T17*POWER($F$16,2)/(POWER(S17/1000,5)*$K$20) -> 9.2923741e-06 | Z17: =IF(AB17>$X$5,1,0) -> 1 | AA17: 80 | AB17: 100 | AC17: =IF(AE17>$X$5,1,0) -> 1 | AD17: 100 | AE17: 125 | BU17: =IF($F$7=BX17,1,0) -> 0 | BV17: 14 | BW17: 50 | BX17: 31.5
A18: Система | B18: ='ОЛ(4)'!A14 -> Отопление | Z18: =IF(AB18>$X$5,1,0) -> 1 | AA18: 100 | AB18: 125 | AC18: =IF(AE18>$X$5,1,0) -> 1 | AD18: 100 | AE18: 160 | BU18: =IF($F$7=BX18,1,0) -> 0 | BV18: 15 | BW18: 50 | BX18: 40
Z19: =IF(AB19>$X$5,1,0) -> 1 | AA19: 100 | AB19: 160 | AC19: =IF(AE19>$X$5,1,0) -> 1 | AD19: 125 | AE19: 200 | BU19: =IF($F$7=BX19,1,0) -> 0 | BV19: 16 | BW19: 65 | BX19: 50
